Workbook

Sheet Дашборд
A1: BADK LIVE — РЕЖИМНА БАЛІСТИЧНА МОДЕЛЬ
A2: Цільова дата | B2: ='Розрахунок'!B2 -> 46307 | D2: День | E2: ='Розрахунок'!B3 -> Понеділок | G2: Версія | H2: ='Налаштування'!G2 -> v2.1-shrink | I2: Цільова ніч | J2: =CHOOSE(WEEKDAY(B2-1,2),"ПН","ВТ","СР","ЧТ","ПТ","СБ","НД")&"→"&CHOOSE(WEEKDAY(B2,2),"ПН","ВТ","СР","ЧТ","ПТ","СБ","НД") -> НД→ПН | K2: Дата після 00:00 | L2: =B2 -> 46307 | M2: Фаза | N2: ='Контроль моделі'!B28 -> PREVIEW | O2: Audit cutoff | P2: ='Розрахунок'!K2 -> 46297 | Q2: ='Контроль моделі'!B31 -> STALE_HISTORY
A4: Місто | B4: R56 | C4: R90 | D4: R180 | E4: R365 | F4: Історична база | G4: Домінантний день режиму | H4: Сила домінанти | I4: Зсув режиму | J4: Домінантний день = цільовому? | K4: Оперативний % | L4: Остання атака | M4: Support R56 • R365 | N4: 95% CI R365 | O4: A-only R365 | P4: Evidence
A5: ='Налаштування'!R39 -> Київ | B5: =IF(IFERROR(VLOOKUP($A5,'Налаштування'!$F$39:$K$52,6,FALSE),"ONBOARDING")="ACTIVE",'Розрахунок'!B5,"") -> 0 | C5: =IF(IFERROR(VLOOKUP($A5,'Налаштування'!$F$39:$K$52,6,FALSE),"ONBOARDING")="ACTIVE",'Розрахунок'!C5,"") -> 0 | D5: =IF(IFERROR(VLOOKUP($A5,'Налаштування'!$F$39:$K$52,6,FALSE),"ONBOARDING")="ACTIVE",'Розрахунок'!D5,"") -> 0.08 | E5: =IF(IFERROR(VLOOKUP($A5,'Налаштування'!$F$39:$K$52,6,FALSE),"ONBOARDING")="ACTIVE",'Розрахунок'!E5,"") -> 0.038461538 | F5: =IF(IFERROR(VLOOKUP($A5,'Налаштування'!$F$39:$K$52,6,FALSE),"ONBOARDING")="ACTIVE",'Розрахунок'!F5,"") -> 0.11679186 | G5: =IF(IFERROR(VLOOKUP($A5,'Налаштування'!$F$39:$K$52,6,FALSE),"ONBOARDING")="ACTIVE",'Розрахунок'!G5,"BACKFILL 365") -> Четвер | H5: =IF(IFERROR(VLOOKUP($A5,'Налаштування'!$F$39:$K$52,6,FALSE),"ONBOARDING")="ACTIVE",'Розрахунок'!H5,"") -> 0.33333333 | I5: =IF(IFERROR(VLOOKUP($A5,'Налаштування'!$F$39:$K$52,6,FALSE),"ONBOARDING")="ACTIVE",'Розрахунок'!J5,"—") -> — | J5: =IF(IFERROR(VLOOKUP($A5,'Налаштування'!$F$39:$K$52,6,FALSE),"ONBOARDING")="ACTIVE",'Розрахунок'!K5,"—") -> Ні | K5: {=IF(IFERROR(VLOOKUP($A5,'Налаштування'!$F$39:$K$52,6,FALSE),"ONBOARDING")="ACTIVE",INDEX('Оперативна оцінка'!$B$24:$N$24,1,MATCH($A5,'Оперативна оцінка'!$B$4:$N$4,0)),"")} | L5: =IFERROR(__xludf.DUMMYFUNCTION("IF(IFERROR(VLOOKUP($A5,'Налаштування'!$F$39:$K$52,6,FALSE),""ONBOARDING"")<>""ACTIVE"",""BACKFILL"",IFERROR(MAX(FILTER(DATEVALUE('Реєстр'!$D$2:$D$5000),'Реєстр'!$B$2:$B$5000=$A5,'Реєстр'!$C$2:$C$5000=""Балістика / швидкісні ракети"",REGEXMATCH('Реєстр'!$A"&"C$2:$AC$5000,""^Включено""))),""—""))"),46305.0) -> 46305 | M5: =IF(IFERROR(VLOOKUP($A5,'Налаштування'!$F$39:$K$52,6,FALSE),"ONBOARDING")="ACTIVE",'Розрахунок'!O5,"") -> 0/8 • 2/52 | N5: =IF(IFERROR(VLOOKUP($A5,'Налаштування'!$F$39:$K$52,6,FALSE),"ONBOARDING")="ACTIVE",TEXT('Розрахунок'!Q5,"0.0%")&"–"&TEXT('Розрахунок'!R5,"0.0%"),"") -> 1,1%–13,0% | O5: =IF(IFERROR(VLOOKUP($A5,'Налаштування'!$F$39:$K$52,6,FALSE),"ONBOARDING")="ACTIVE",'Розрахунок'!S5,"") -> 0.038461538 | P5: =IFERROR("2src "&TEXT(COUNTIFS('Реєстр'!$B$2:$B$5000,$A5,'Реєстр'!$C$2:$C$5000,"Балістика / швидкісні ракети",'Реєстр'!$AC$2:$AC$5000,"Включено*",'Реєстр'!$AR$2:$AR$5000,"MODEL-365",'Реєстр'!$O$2:$O$5000,"<>")/COUNTIFS('Реєстр'!$B$2:$B$5000,$A5,'Реєстр'!$C$2:$C$5000,"Балістика / швидкісні ракети",'Реєстр'!$AC$2:$AC$5000,"Включено*",'Реєстр'!$AR$2:$AR$5000,"MODEL-365"),"0%")&" • B "&TEXT(COUNTIFS('Реєстр'!$B$2:$B$5000,$A5,'Реєстр'!$C$2:$C$5000,"Балістика / швидкісні ракети",'Реєстр'!$AC$2:$AC$5000,"Включено*",'Реєстр'!$AR$2:$AR$5000,"MODEL-365",'Реєстр'!$L$2:$L$5000,"B*")/COUNTIFS('Реєстр'!$B$2:$B$5000,$A5,'Реєстр'!$C$2:$C$5000,"Балістика / швидкісні ракети",'Реєстр'!$AC$2:$AC$5000,"Включено*",'Реєстр'!$AR$2:$AR$5000,"MODEL-365"),"0%"),"—") -> 2src 100% • B 4%
A6: ='Налаштування'!R40 -> Дніпро | B6: =IF(IFERROR(VLOOKUP($A6,'Налаштування'!$F$39:$K$52,6,FALSE),"ONBOARDING")="ACTIVE",'Розрахунок'!B6,"") -> 0 | C6: =IF(IFERROR(VLOOKUP($A6,'Налаштування'!$F$39:$K$52,6,FALSE),"ONBOARDING")="ACTIVE",'Розрахунок'!C6,"") -> 0 | D6: =IF(IFERROR(VLOOKUP($A6,'Налаштування'!$F$39:$K$52,6,FALSE),"ONBOARDING")="ACTIVE",'Розрахунок'!D6,"") -> 0.08 | E6: =IF(IFERROR(VLOOKUP($A6,'Налаштування'!$F$39:$K$52,6,FALSE),"ONBOARDING")="ACTIVE",'Розрахунок'!E6,"") -> 0.076923077 | F6: =IF(IFERROR(VLOOKUP($A6,'Налаштування'!$F$39:$K$52,6,FALSE),"ONBOARDING")="ACTIVE",'Розрахунок'!F6,"") -> 0.049345885 | G6: =IF(IFERROR(VLOOKUP($A6,'Налаштування'!$F$39:$K$52,6,FALSE),"ONBOARDING")="ACTIVE",'Розрахунок'!G6,"BACKFILL 365") -> Вівторок/Середа/Субота • по 1 (нічия) | H6: =IF(IFERROR(VLOOKUP($A6,'Налаштування'!$F$39:$K$52,6,FALSE),"ONBOARDING")="ACTIVE",'Розрахунок'!H6,"") -> 0 | I6: =IF(IFERROR(VLOOKUP($A6,'Налаштування'!$F$39:$K$52,6,FALSE),"ONBOARDING")="ACTIVE",'Розрахунок'!J6,"—") -> — | J6: =IF(IFERROR(VLOOKUP($A6,'Налаштування'!$F$39:$K$52,6,FALSE),"ONBOARDING")="ACTIVE",'Розрахунок'!K6,"—") -> — | K6: {=IF(IFERROR(VLOOKUP($A6,'Налаштування'!$F$39:$K$52,6,FALSE),"ONBOARDING")="ACTIVE",INDEX('Оперативна оцінка'!$B$24:$N$24,1,MATCH($A6,'Оперативна оцінка'!$B$4:$N$4,0)),"")} | L6: =IFERROR(__xludf.DUMMYFUNCTION("IF(IFERROR(VLOOKUP($A6,'Налаштування'!$F$39:$K$52,6,FALSE),""ONBOARDING"")<>""ACTIVE"",""BACKFILL"",IFERROR(MAX(FILTER(DATEVALUE('Реєстр'!$D$2:$D$5000),'Реєстр'!$B$2:$B$5000=$A6,'Реєстр'!$C$2:$C$5000=""Балістика / швидкісні ракети"",REGEXMATCH('Реєстр'!$A"&"C$2:$AC$5000,""^Включено""))),""—""))"),46302.0) -> 46302 | M6: =IF(IFERROR(VLOOKUP($A6,'Налаштування'!$F$39:$K$52,6,FALSE),"ONBOARDING")="ACTIVE",'Розрахунок'!O6,"") -> 0/8 • 4/52 | N6: =IF(IFERROR(VLOOKUP($A6,'Налаштування'!$F$39:$K$52,6,FALSE),"ONBOARDING")="ACTIVE",TEXT('Розрахунок'!Q6,"0.0%")&"–"&TEXT('Розрахунок'!R6,"0.0%"),"") -> 3,0%–18,2% | O6: =IF(IFERROR(VLOOKUP($A6,'Налаштування'!$F$39:$K$52,6,FALSE),"ONBOARDING")="ACTIVE",'Розрахунок'!S6,"") -> 0.038461538 | P6: =IFERROR("2src "&TEXT(COUNTIFS('Реєстр'!$B$2:$B$5000,$A6,'Реєстр'!$C$2:$C$5000,"Балістика / швидкісні ракети",'Реєстр'!$AC$2:$AC$5000,"Включено*",'Реєстр'!$AR$2:$AR$5000,"MODEL-365",'Реєстр'!$O$2:$O$5000,"<>")/COUNTIFS('Реєстр'!$B$2:$B$5000,$A6,'Реєстр'!$C$2:$C$5000,"Балістика / швидкісні ракети",'Реєстр'!$AC$2:$AC$5000,"Включено*",'Реєстр'!$AR$2:$AR$5000,"MODEL-365"),"0%")&" • B "&TEXT(COUNTIFS('Реєстр'!$B$2:$B$5000,$A6,'Реєстр'!$C$2:$C$5000,"Балістика / швидкісні ракети",'Реєстр'!$AC$2:$AC$5000,"Включено*",'Реєстр'!$AR$2:$AR$5000,"MODEL-365",'Реєстр'!$L$2:$L$5000,"B*")/COUNTIFS('Реєстр'!$B$2:$B$5000,$A6,'Реєстр'!$C$2:$C$5000,"Балістика / швидкісні ракети",'Реєстр'!$AC$2:$AC$5000,"Включено*",'Реєстр'!$AR$2:$AR$5000,"MODEL-365"),"0%"),"—") -> 2src 100% • B 27%
A7: ='Налаштування'!R41 -> Житомир | B7: =IF(IFERROR(VLOOKUP($A7,'Налаштування'!$F$39:$K$52,6,FALSE),"ONBOARDING")="ACTIVE",'Розрахунок'!B7,"") -> 0 | C7: =IF(IFERROR(VLOOKUP($A7,'Налаштування'!$F$39:$K$52,6,FALSE),"ONBOARDING")="ACTIVE",'Розрахунок'!C7,"") -> 0 | D7: =IF(IFERROR(VLOOKUP($A7,'Налаштування'!$F$39:$K$52,6,FALSE),"ONBOARDING")="ACTIVE",'Розрахунок'!D7,"") -> 0 | E7: =IF(IFERROR(VLOOKUP($A7,'Налаштування'!$F$39:$K$52,6,FALSE),"ONBOARDING")="ACTIVE",'Розрахунок'!E7,"") -> 0 | F7: =IF(IFERROR(VLOOKUP($A7,'Налаштування'!$F$39:$K$52,6,FALSE),"ONBOARDING")="ACTIVE",'Розрахунок'!F7,"") -> 0.00029077646 | G7: =IF(IFERROR(VLOOKUP($A7,'Налаштування'!$F$39:$K$52,6,FALSE),"ONBOARDING")="ACTIVE",'Розрахунок'!G7,"BACKFILL 365") -> Немає | H7: =IF(IFERROR(VLOOKUP($A7,'Налаштування'!$F$39:$K$52,6,FALSE),"ONBOARDING")="ACTIVE",'Розрахунок'!H7,"") -> 0 | I7: =IF(IFERROR(VLOOKUP($A7,'Налаштування'!$F$39:$K$52,6,FALSE),"ONBOARDING")="ACTIVE",'Розрахунок'!J7,"—") -> — | J7: =IF(IFERROR(VLOOKUP($A7,'Налаштування'!$F$39:$K$52,6,FALSE),"ONBOARDING")="ACTIVE",'Розрахунок'!K7,"—") -> — | K7: {=IF(IFERROR(VLOOKUP($A7,'Налаштування'!$F$39:$K$52,6,FALSE),"ONBOARDING")="ACTIVE",INDEX('Оперативна оцінка'!$B$24:$N$24,1,MATCH($A7,'Оперативна оцінка'!$B$4:$N$4,0)),"")} | L7: =IFERROR(__xludf.DUMMYFUNCTION("IF(IFERROR(VLOOKUP($A7,'Налаштування'!$F$39:$K$52,6,FALSE),""ONBOARDING"")<>""ACTIVE"",""BACKFILL"",IFERROR(MAX(FILTER(DATEVALUE('Реєстр'!$D$2:$D$5000),'Реєстр'!$B$2:$B$5000=$A7,'Реєстр'!$C$2:$C$5000=""Балістика / швидкісні ракети"",REGEXMATCH('Реєстр'!$A"&"C$2:$AC$5000,""^Включено""))),""—""))"),45963.0) -> 45963 | M7: =IF(IFERROR(VLOOKUP($A7,'Налаштування'!$F$39:$K$52,6,FALSE),"ONBOARDING")="ACTIVE",'Розрахунок'!O7,"") -> 0/8 • 0/52 | N7: =IF(IFERROR(VLOOKUP($A7,'Налаштування'!$F$39:$K$52,6,FALSE),"ONBOARDING")="ACTIVE",TEXT('Розрахунок'!Q7,"0.0%")&"–"&TEXT('Розрахунок'!R7,"0.0%"),"") -> 0,0%–6,9% | O7: =IF(IFERROR(VLOOKUP($A7,'Налаштування'!$F$39:$K$52,6,FALSE),"ONBOARDING")="ACTIVE",'Розрахунок'!S7,"") -> 0 | P7: =IFERROR("2src "&TEXT(COUNTIFS('Реєстр'!$B$2:$B$5000,$A7,'Реєстр'!$C$2:$C$5000,"Балістика / швидкісні ракети",'Реєстр'!$AC$2:$AC$5000,"Включено*",'Реєстр'!$AR$2:$AR$5000,"MODEL-365",'Реєстр'!$O$2:$O$5000,"<>")/COUNTIFS('Реєстр'!$B$2:$B$5000,$A7,'Реєстр'!$C$2:$C$5000,"Балістика / швидкісні ракети",'Реєстр'!$AC$2:$AC$5000,"Включено*",'Реєстр'!$AR$2:$AR$5000,"MODEL-365"),"0%")&" • B "&TEXT(COUNTIFS('Реєстр'!$B$2:$B$5000,$A7,'Реєстр'!$C$2:$C$5000,"Балістика / швидкісні ракети",'Реєстр'!$AC$2:$AC$5000,"Включено*",'Реєстр'!$AR$2:$AR$5000,"MODEL-365",'Реєстр'!$L$2:$L$5000,"B*")/COUNTIFS('Реєстр'!$B$2:$B$5000,$A7,'Реєстр'!$C$2:$C$5000,"Балістика / швидкісні ракети",'Реєстр'!$AC$2:$AC$5000,"Включено*",'Реєстр'!$AR$2:$AR$5000,"MODEL-365"),"0%"),"—") -> 2src 100% • B 0%
A8: ='Налаштування'!R42 -> Запоріжжя | B8: =IF(IFERROR(VLOOKUP($A8,'Налаштування'!$F$39:$K$52,6,FALSE),"ONBOARDING")="ACTIVE",'Розрахунок'!B8,"") -> 0 | C8: =IF(IFERROR(VLOOKUP($A8,'Налаштування'!$F$39:$K$52,6,FALSE),"ONBOARDING")="ACTIVE",'Розрахунок'!C8,"") -> 0 | D8: =IF(IFERROR(VLOOKUP($A8,'Налаштування'!$F$39:$K$52,6,FALSE),"ONBOARDING")="ACTIVE",'Розрахунок'!D8,"") -> 0 | E8: =IF(IFERROR(VLOOKUP($A8,'Налаштування'!$F$39:$K$52,6,FALSE),"ONBOARDING")="ACTIVE",'Розрахунок'!E8,"") -> 0 | F8: =IF(IFERROR(VLOOKUP($A8,'Налаштування'!$F$39:$K$52,6,FALSE),"ONBOARDING")="ACTIVE",'Розрахунок'!F8,"") -> 0.026823138 | G8: =IF(IFERROR(VLOOKUP($A8,'Налаштування'!$F$39:$K$52,6,FALSE),"ONBOARDING")="ACTIVE",'Розрахунок'!G8,"BACKFILL 365") -> Середа/Четвер • по 2 (нічия) | H8: =IF(IFERROR(VLOOKUP($A8,'Налаштування'!$F$39:$K$52,6,FALSE),"ONBOARDING")="ACTIVE",'Розрахунок'!H8,"") -> 0 | I8: =IF(IFERROR(VLOOKUP($A8,'Налаштування'!$F$39:$K$52,6,FALSE),"ONBOARDING")="ACTIVE",'Розрахунок'!J8,"—") -> — | J8: =IF(IFERROR(VLOOKUP($A8,'Налаштування'!$F$39:$K$52,6,FALSE),"ONBOARDING")="ACTIVE",'Розрахунок'!K8,"—") -> — | K8: {=IF(IFERROR(VLOOKUP($A8,'Налаштування'!$F$39:$K$52,6,FALSE),"ONBOARDING")="ACTIVE",INDEX('Оперативна оцінка'!$B$24:$N$24,1,MATCH($A8,'Оперативна оцінка'!$B$4:$N$4,0)),"")} | L8: =IFERROR(__xludf.DUMMYFUNCTION("IF(IFERROR(VLOOKUP($A8,'Налаштування'!$F$39:$K$52,6,FALSE),""ONBOARDING"")<>""ACTIVE"",""BACKFILL"",IFERROR(MAX(FILTER(DATEVALUE('Реєстр'!$D$2:$D$5000),'Реєстр'!$B$2:$B$5000=$A8,'Реєстр'!$C$2:$C$5000=""Балістика / швидкісні ракети"",REGEXMATCH('Реєстр'!$A"&"C$2:$AC$5000,""^Включено""))),""—""))"),46302.0) -> 46302 | M8: =IF(IFERROR(VLOOKUP($A8,'Налаштування'!$F$39:$K$52,6,FALSE),"ONBOARDING")="ACTIVE",'Розрахунок'!O8,"") -> 0/8 • 0/52 | N8: =IF(IFERROR(VLOOKUP($A8,'Налаштування'!$F$39:$K$52,6,FALSE),"ONBOARDING")="ACTIVE",TEXT('Розрахунок'!Q8,"0.0%")&"–"&TEXT('Розрахунок'!R8,"0.0%"),"") -> 0,0%–6,9% | O8: =IF(IFERROR(VLOOKUP($A8,'Налаштування'!$F$39:$K$52,6,FALSE),"ONBOARDING")="ACTIVE",'Розрахунок'!S8,"") -> 0 | P8: =IFERROR("2src "&TEXT(COUNTIFS('Реєстр'!$B$2:$B$5000,$A8,'Реєстр'!$C$2:$C$5000,"Балістика / швидкісні ракети",'Реєстр'!$AC$2:$AC$5000,"Включено*",'Реєстр'!$AR$2:$AR$5000,"MODEL-365",'Реєстр'!$O$2:$O$5000,"<>")/COUNTIFS('Реєстр'!$B$2:$B$5000,$A8,'Реєстр'!$C$2:$C$5000,"Балістика / швидкісні ракети",'Реєстр'!$AC$2:$AC$5000,"Включено*",'Реєстр'!$AR$2:$AR$5000,"MODEL-365"),"0%")&" • B "&TEXT(COUNTIFS('Реєстр'!$B$2:$B$5000,$A8,'Реєстр'!$C$2:$C$5000,"Балістика / швидкісні ракети",'Реєстр'!$AC$2:$AC$5000,"Включено*",'Реєстр'!$AR$2:$AR$5000,"MODEL-365",'Реєстр'!$L$2:$L$5000,"B*")/COUNTIFS('Реєстр'!$B$2:$B$5000,$A8,'Реєстр'!$C$2:$C$5000,"Балістика / швидкісні ракети",'Реєстр'!$AC$2:$AC$5000,"Включено*",'Реєстр'!$AR$2:$AR$5000,"MODEL-365"),"0%"),"—") -> 2src 100% • B 46%
A9: ='Налаштування'!R43 -> Миколаїв | B9: =IF(IFERROR(VLOOKUP($A9,'Налаштування'!$F$39:$K$52,6,FALSE),"ONBOARDING")="ACTIVE",'Розрахунок'!B9,"") -> 0 | C9: =IF(IFERROR(VLOOKUP($A9,'Налаштування'!$F$39:$K$52,6,FALSE),"ONBOARDING")="ACTIVE",'Розрахунок'!C9,"") -> 0 | D9: =IF(IFERROR(VLOOKUP($A9,'Налаштування'!$F$39:$K$52,6,FALSE),"ONBOARDING")="ACTIVE",'Розрахунок'!D9,"") -> 0 | E9: =IF(IFERROR(VLOOKUP($A9,'Налаштування'!$F$39:$K$52,6,FALSE),"ONBOARDING")="ACTIVE",'Розрахунок'!E9,"") -> 0 | F9: =IF(IFERROR(VLOOKUP($A9,'Налаштування'!$F$39:$K$52,6,FALSE),"ONBOARDING")="ACTIVE",'Розрахунок'!F9,"") -> 0.0089819532 | G9: =IF(IFERROR(VLOOKUP($A9,'Налаштування'!$F$39:$K$52,6,FALSE),"ONBOARDING")="ACTIVE",'Розрахунок'!G9,"BACKFILL 365") -> Середа/П’ятниця • по 1 (нічия) | H9: =IF(IFERROR(VLOOKUP($A9,'Налаштування'!$F$39:$K$52,6,FALSE),"ONBOARDING")="ACTIVE",'Розрахунок'!H9,"") -> 0 | I9: =IF(IFERROR(VLOOKUP($A9,'Налаштування'!$F$39:$K$52,6,FALSE),"ONBOARDING")="ACTIVE",'Розрахунок'!J9,"—") -> — | J9: =IF(IFERROR(VLOOKUP($A9,'Налаштування'!$F$39:$K$52,6,FALSE),"ONBOARDING")="ACTIVE",'Розрахунок'!K9,"—") -> — | K9: {=IF(IFERROR(VLOOKUP($A9,'Налаштування'!$F$39:$K$52,6,FALSE),"ONBOARDING")="ACTIVE",INDEX('Оперативна оцінка'!$B$24:$N$24,1,MATCH($A9,'Оперативна оцінка'!$B$4:$N$4,0)),"")} | L9: =IFERROR(__xludf.DUMMYFUNCTION("IF(IFERROR(VLOOKUP($A9,'Налаштування'!$F$39:$K$52,6,FALSE),""ONBOARDING"")<>""ACTIVE"",""BACKFILL"",IFERROR(MAX(FILTER(DATEVALUE('Реєстр'!$D$2:$D$5000),'Реєстр'!$B$2:$B$5000=$A9,'Реєстр'!$C$2:$C$5000=""Балістика / швидкісні ракети"",REGEXMATCH('Реєстр'!$A"&"C$2:$AC$5000,""^Включено""))),""—""))"),46297.0) -> 46297 | M9: =IF(IFERROR(VLOOKUP($A9,'Налаштування'!$F$39:$K$52,6,FALSE),"ONBOARDING")="ACTIVE",'Розрахунок'!O9,"") -> 0/8 • 0/52 | N9: =IF(IFERROR(VLOOKUP($A9,'Налаштування'!$F$39:$K$52,6,FALSE),"ONBOARDING")="ACTIVE",TEXT('Розрахунок'!Q9,"0.0%")&"–"&TEXT('Розрахунок'!R9,"0.0%"),"") -> 0,0%–6,9% | O9: =IF(IFERROR(VLOOKUP($A9,'Налаштування'!$F$39:$K$52,6,FALSE),"ONBOARDING")="ACTIVE",'Розрахунок'!S9,"") -> 0 | P9: =IFERROR("2src "&TEXT(COUNTIFS('Реєстр'!$B$2:$B$5000,$A9,'Реєстр'!$C$2:$C$5000,"Балістика / швидкісні ракети",'Реєстр'!$AC$2:$AC$5000,"Включено*",'Реєстр'!$AR$2:$AR$5000,"MODEL-365",'Реєстр'!$O$2:$O$5000,"<>")/COUNTIFS('Реєстр'!$B$2:$B$5000,$A9,'Реєстр'!$C$2:$C$5000,"Балістика / швидкісні ракети",'Реєстр'!$AC$2:$AC$5000,"Включено*",'Реєстр'!$AR$2:$AR$5000,"MODEL-365"),"0%")&" • B "&TEXT(COUNTIFS('Реєстр'!$B$2:$B$5000,$A9,'Реєстр'!$C$2:$C$5000,"Балістика / швидкісні ракети",'Реєстр'!$AC$2:$AC$5000,"Включено*",'Реєстр'!$AR$2:$AR$5000,"MODEL-365",'Реєстр'!$L$2:$L$5000,"B*")/COUNTIFS('Реєстр'!$B$2:$B$5000,$A9,'Реєстр'!$C$2:$C$5000,"Балістика / швидкісні ракети",'Реєстр'!$AC$2:$AC$5000,"Включено*",'Реєстр'!$AR$2:$AR$5000,"MODEL-365"),"0%"),"—") -> 2src 100% • B 40%
A10: ='Налаштування'!R44 -> Одеса | B10: =IF(IFERROR(VLOOKUP($A10,'Налаштування'!$F$39:$K$52,6,FALSE),"ONBOARDING")="ACTIVE",'Розрахунок'!B10,"") -> 0 | C10: =IF(IFERROR(VLOOKUP($A10,'Налаштування'!$F$39:$K$52,6,FALSE),"ONBOARDING")="ACTIVE",'Розрахунок'!C10,"") -> 0 | D10: =IF(IFERROR(VLOOKUP($A10,'Налаштування'!$F$39:$K$52,6,FALSE),"ONBOARDING")="ACTIVE",'Розрахунок'!D10,"") -> 0.04 | E10: =IF(IFERROR(VLOOKUP($A10,'Налаштування'!$F$39:$K$52,6,FALSE),"ONBOARDING")="ACTIVE",'Розрахунок'!E10,"") -> 0.076923077 | F10: =IF(IFERROR(VLOOKUP($A10,'Налаштування'!$F$39:$K$52,6,FALSE),"ONBOARDING")="ACTIVE",'Розрахунок'!F10,"") -> 0.061666566 | G10: =IF(IFERROR(VLOOKUP($A10,'Налаштування'!$F$39:$K$52,6,FALSE),"ONBOARDING")="ACTIVE",'Розрахунок'!G10,"BACKFILL 365") -> Вівторок/Середа/Четвер • по 1 (нічия) | H10: =IF(IFERROR(VLOOKUP($A10,'Налаштування'!$F$39:$K$52,6,FALSE),"ONBOARDING")="ACTIVE",'Розрахунок'!H10,"") -> 0 | I10: =IF(IFERROR(VLOOKUP($A10,'Налаштування'!$F$39:$K$52,6,FALSE),"ONBOARDING")="ACTIVE",'Розрахунок'!J10,"—") -> — | J10: =IF(IFERROR(VLOOKUP($A10,'Налаштування'!$F$39:$K$52,6,FALSE),"ONBOARDING")="ACTIVE",'Розрахунок'!K10,"—") -> — | K10: {=IF(IFERROR(VLOOKUP($A10,'Налаштування'!$F$39:$K$52,6,FALSE),"ONBOARDING")="ACTIVE",INDEX('Оперативна оцінка'!$B$24:$N$24,1,MATCH($A10,'Оперативна оцінка'!$B$4:$N$4,0)),"")} | L10: =IFERROR(__xludf.DUMMYFUNCTION("IF(IFERROR(VLOOKUP($A10,'Налаштування'!$F$39:$K$52,6,FALSE),""ONBOARDING"")<>""ACTIVE"",""BACKFILL"",IFERROR(MAX(FILTER(DATEVALUE('Реєстр'!$D$2:$D$5000),'Реєстр'!$B$2:$B$5000=$A10,'Реєстр'!$C$2:$C$5000=""Балістика / швидкісні ракети"",REGEXMATCH('Реєстр'!"&"$AC$2:$AC$5000,""^Включено""))),""—""))"),46289.0) -> 46289 | M10: =IF(IFERROR(VLOOKUP($A10,'Налаштування'!$F$39:$K$52,6,FALSE),"ONBOARDING")="ACTIVE",'Розрахунок'!O10,"") -> 0/8 • 4/52 | N10: =IF(IFERROR(VLOOKUP($A10,'Налаштування'!$F$39:$K$52,6,FALSE),"ONBOARDING")="ACTIVE",TEXT('Розрахунок'!Q10,"0.0%")&"–"&TEXT('Розрахунок'!R10,"0.0%"),"") -> 3,0%–18,2% | O10: =IF(IFERROR(VLOOKUP($A10,'Налаштування'!$F$39:$K$52,6,FALSE),"ONBOARDING")="ACTIVE",'Розрахунок'!S10,"") -> 0.076923077 | P10: =IFERROR("2src "&TEXT(COUNTIFS('Реєстр'!$B$2:$B$5000,$A10,'Реєстр'!$C$2:$C$5000,"Балістика / швидкісні ракети",'Реєстр'!$AC$2:$AC$5000,"Включено*",'Реєстр'!$AR$2:$AR$5000,"MODEL-365",'Реєстр'!$O$2:$O$5000,"<>")/COUNTIFS('Реєстр'!$B$2:$B$5000,$A10,'Реєстр'!$C$2:$C$5000,"Балістика / швидкісні ракети",'Реєстр'!$AC$2:$AC$5000,"Включено*",'Реєстр'!$AR$2:$AR$5000,"MODEL-365"),"0%")&" • B "&TEXT(COUNTIFS('Реєстр'!$B$2:$B$5000,$A10,'Реєстр'!$C$2:$C$5000,"Балістика / швидкісні ракети",'Реєстр'!$AC$2:$AC$5000,"Включено*",'Реєстр'!$AR$2:$AR$5000,"MODEL-365",'Реєстр'!$L$2:$L$5000,"B*")/COUNTIFS('Реєстр'!$B$2:$B$5000,$A10,'Реєстр'!$C$2:$C$5000,"Балістика / швидкісні ракети",'Реєстр'!$AC$2:$AC$5000,"Включено*",'Реєстр'!$AR$2:$AR$5000,"MODEL-365"),"0%"),"—") -> 2src 100% • B 12%
A11: ='Налаштування'!R45 -> Харків | B11: =IF(IFERROR(VLOOKUP($A11,'Налаштування'!$F$39:$K$52,6,FALSE),"ONBOARDING")="ACTIVE",'Розрахунок'!B11,"") -> 0 | C11: =IF(IFERROR(VLOOKUP($A11,'Налаштування'!$F$39:$K$52,6,FALSE),"ONBOARDING")="ACTIVE",'Розрахунок'!C11,"") -> 0 | D11: =IF(IFERROR(VLOOKUP($A11,'Налаштування'!$F$39:$K$52,6,FALSE),"ONBOARDING")="ACTIVE",'Розрахунок'!D11,"") -> 0.12 | E11: =IF(IFERROR(VLOOKUP($A11,'Налаштування'!$F$39:$K$52,6,FALSE),"ONBOARDING")="ACTIVE",'Розрахунок'!E11,"") -> 0.057692308 | F11: =IF(IFERROR(VLOOKUP($A11,'Налаштування'!$F$39:$K$52,6,FALSE),"ONBOARDING")="ACTIVE",'Розрахунок'!F11,"") -> 0.042414339 | G11: =IF(IFERROR(VLOOKUP($A11,'Налаштування'!$F$39:$K$52,6,FALSE),"ONBOARDING")="ACTIVE",'Розрахунок'!G11,"BACKFILL 365") -> Немає | H11: =IF(IFERROR(VLOOKUP($A11,'Налаштування'!$F$39:$K$52,6,FALSE),"ONBOARDING")="ACTIVE",'Розрахунок'!H11,"") -> 0 | I11: =IF(IFERROR(VLOOKUP($A11,'Налаштування'!$F$39:$K$52,6,FALSE),"ONBOARDING")="ACTIVE",'Розрахунок'!J11,"—") -> — | J11: =IF(IFERROR(VLOOKUP($A11,'Налаштування'!$F$39:$K$52,6,FALSE),"ONBOARDING")="ACTIVE",'Розрахунок'!K11,"—") -> — | K11: {=IF(IFERROR(VLOOKUP($A11,'Налаштування'!$F$39:$K$52,6,FALSE),"ONBOARDING")="ACTIVE",INDEX('Оперативна оцінка'!$B$24:$N$24,1,MATCH($A11,'Оперативна оцінка'!$B$4:$N$4,0)),"")} | L11: =IFERROR(__xludf.DUMMYFUNCTION("IF(IFERROR(VLOOKUP($A11,'Налаштування'!$F$39:$K$52,6,FALSE),""ONBOARDING"")<>""ACTIVE"",""BACKFILL"",IFERROR(MAX(FILTER(DATEVALUE('Реєстр'!$D$2:$D$5000),'Реєстр'!$B$2:$B$5000=$A11,'Реєстр'!$C$2:$C$5000=""Балістика / швидкісні ракети"",REGEXMATCH('Реєстр'!"&"$AC$2:$AC$5000,""^Включено""))),""—""))"),46211.0) -> 46211 | M11: =IF(IFERROR(VLOOKUP($A11,'Налаштування'!$F$39:$K$52,6,FALSE),"ONBOARDING")="ACTIVE",'Розрахунок'!O11,"") -> 0/8 • 3/52 | N11: =IF(IFERROR(VLOOKUP($A11,'Налаштування'!$F$39:$K$52,6,FALSE),"ONBOARDING")="ACTIVE",TEXT('Розрахунок'!Q11,"0.0%")&"–"&TEXT('Розрахунок'!R11,"0.0%"),"") -> 2,0%–15,6% | O11: =IF(IFERROR(VLOOKUP($A11,'Налаштування'!$F$39:$K$52,6,FALSE),"ONBOARDING")="ACTIVE",'Розрахунок'!S11,"") -> 0.038461538 | P11: =IFERROR("2src "&TEXT(COUNTIFS('Реєстр'!$B$2:$B$5000,$A11,'Реєстр'!$C$2:$C$5000,"Балістика / швидкісні ракети",'Реєстр'!$AC$2:$AC$5000,"Включено*",'Реєстр'!$AR$2:$AR$5000,"MODEL-365",'Реєстр'!$O$2:$O$5000,"<>")/COUNTIFS('Реєстр'!$B$2:$B$5000,$A11,'Реєстр'!$C$2:$C$5000,"Балістика / швидкісні ракети",'Реєстр'!$AC$2:$AC$5000,"Включено*",'Реєстр'!$AR$2:$AR$5000,"MODEL-365"),"0%")&" • B "&TEXT(COUNTIFS('Реєстр'!$B$2:$B$5000,$A11,'Реєстр'!$C$2:$C$5000,"Балістика / швидкісні ракети",'Реєстр'!$AC$2:$AC$5000,"Включено*",'Реєстр'!$AR$2:$AR$5000,"MODEL-365",'Реєстр'!$L$2:$L$5000,"B*")/COUNTIFS('Реєстр'!$B$2:$B$5000,$A11,'Реєстр'!$C$2:$C$5000,"Балістика / швидкісні ракети",'Реєстр'!$AC$2:$AC$5000,"Включено*",'Реєстр'!$AR$2:$AR$5000,"MODEL-365"),"0%"),"—") -> 2src 100% • B 25%
A12: ='Налаштування'!R46 -> Херсон | B12: =IF(IFERROR(VLOOKUP($A12,'Налаштування'!$F$39:$K$52,6,FALSE),"ONBOARDING")="ACTIVE",'Розрахунок'!B12,"") -> 0 | C12: =IF(IFERROR(VLOOKUP($A12,'Налаштування'!$F$39:$K$52,6,FALSE),"ONBOARDING")="ACTIVE",'Розрахунок'!C12,"") -> 0 | D12: =IF(IFERROR(VLOOKUP($A12,'Налаштування'!$F$39:$K$52,6,FALSE),"ONBOARDING")="ACTIVE",'Розрахунок'!D12,"") -> 0 | E12: =IF(IFERROR(VLOOKUP($A12,'Налаштування'!$F$39:$K$52,6,FALSE),"ONBOARDING")="ACTIVE",'Розрахунок'!E12,"") -> 0 | F12: =IF(IFERROR(VLOOKUP($A12,'Налаштування'!$F$39:$K$52,6,FALSE),"ONBOARDING")="ACTIVE",'Розрахунок'!F12,"") -> 0 | G12: =IF(IFERROR(VLOOKUP($A12,'Налаштування'!$F$39:$K$52,6,FALSE),"ONBOARDING")="ACTIVE",'Розрахунок'!G12,"BACKFILL 365") -> Немає | H12: =IF(IFERROR(VLOOKUP($A12,'Налаштування'!$F$39:$K$52,6,FALSE),"ONBOARDING")="ACTIVE",'Розрахунок'!H12,"") -> 0 | I12: =IF(IFERROR(VLOOKUP($A12,'Налаштування'!$F$39:$K$52,6,FALSE),"ONBOARDING")="ACTIVE",'Розрахунок'!J12,"—") -> — | J12: =IF(IFERROR(VLOOKUP($A12,'Налаштування'!$F$39:$K$52,6,FALSE),"ONBOARDING")="ACTIVE",'Розрахунок'!K12,"—") -> — | K12: {=IF(IFERROR(VLOOKUP($A12,'Налаштування'!$F$39:$K$52,6,FALSE),"ONBOARDING")="ACTIVE",INDEX('Оперативна оцінка'!$B$24:$N$24,1,MATCH($A12,'Оперативна оцінка'!$B$4:$N$4,0)),"")} | L12: =IFERROR(__xludf.DUMMYFUNCTION("IF(IFERROR(VLOOKUP($A12,'Налаштування'!$F$39:$K$52,6,FALSE),""ONBOARDING"")<>""ACTIVE"",""BACKFILL"",IFERROR(MAX(FILTER(DATEVALUE('Реєстр'!$D$2:$D$5000),'Реєстр'!$B$2:$B$5000=$A12,'Реєстр'!$C$2:$C$5000=""Балістика / швидкісні ракети"",REGEXMATCH('Реєстр'!"&"$AC$2:$AC$5000,""^Включено""))),""—""))"),45597.0) -> 45597 | M12: =IF(IFERROR(VLOOKUP($A12,'Налаштування'!$F$39:$K$52,6,FALSE),"ONBOARDING")="ACTIVE",'Розрахунок'!O12,"") -> 0/8 • 0/52 | N12: =IF(IFERROR(VLOOKUP($A12,'Налаштування'!$F$39:$K$52,6,FALSE),"ONBOARDING")="ACTIVE",TEXT('Розрахунок'!Q12,"0.0%")&"–"&TEXT('Розрахунок'!R12,"0.0%"),"") -> 0,0%–6,9% | O12: =IF(IFERROR(VLOOKUP($A12,'Налаштування'!$F$39:$K$52,6,FALSE),"ONBOARDING")="ACTIVE",'Розрахунок'!S12,"") -> 0 | P12: =IFERROR("2src "&TEXT(COUNTIFS('Реєстр'!$B$2:$B$5000,$A12,'Реєстр'!$C$2:$C$5000,"Балістика / швидкісні ракети",'Реєстр'!$AC$2:$AC$5000,"Включено*",'Реєстр'!$AR$2:$AR$5000,"MODEL-365",'Реєстр'!$O$2:$O$5000,"<>")/COUNTIFS('Реєстр'!$B$2:$B$5000,$A12,'Реєстр'!$C$2:$C$5000,"Балістика / швидкісні ракети",'Реєстр'!$AC$2:$AC$5000,"Включено*",'Реєстр'!$AR$2:$AR$5000,"MODEL-365"),"0%")&" • B "&TEXT(COUNTIFS('Реєстр'!$B$2:$B$5000,$A12,'Реєстр'!$C$2:$C$5000,"Балістика / швидкісні ракети",'Реєстр'!$AC$2:$AC$5000,"Включено*",'Реєстр'!$AR$2:$AR$5000,"MODEL-365",'Реєстр'!$L$2:$L$5000,"B*")/COUNTIFS('Реєстр'!$B$2:$B$5000,$A12,'Реєстр'!$C$2:$C$5000,"Балістика / швидкісні ракети",'Реєстр'!$AC$2:$AC$5000,"Включено*",'Реєстр'!$AR$2:$AR$5000,"MODEL-365"),"0%"),"—") -> —
A13: ='Налаштування'!R47 -> Чернігів | B13: =IF(IFERROR(VLOOKUP($A13,'Налаштування'!$F$39:$K$52,6,FALSE),"ONBOARDING")="ACTIVE",'Розрахунок'!B13,"") -> 0 | C13: =IF(IFERROR(VLOOKUP($A13,'Налаштування'!$F$39:$K$52,6,FALSE),"ONBOARDING")="ACTIVE",'Розрахунок'!C13,"") -> 0 | D13: =IF(IFERROR(VLOOKUP($A13,'Налаштування'!$F$39:$K$52,6,FALSE),"ONBOARDING")="ACTIVE",'Розрахунок'!D13,"") -> 0 | E13: =IF(IFERROR(VLOOKUP($A13,'Налаштування'!$F$39:$K$52,6,FALSE),"ONBOARDING")="ACTIVE",'Розрахунок'!E13,"") -> 0.019230769 | F13: =IF(IFERROR(VLOOKUP($A13,'Налаштування'!$F$39:$K$52,6,FALSE),"ONBOARDING")="ACTIVE",'Розрахунок'!F13,"") -> 0.004818431 | G13: =IF(IFERROR(VLOOKUP($A13,'Налаштування'!$F$39:$K$52,6,FALSE),"ONBOARDING")="ACTIVE",'Розрахунок'!G13,"BACKFILL 365") -> Немає | H13: =IF(IFERROR(VLOOKUP($A13,'Налаштування'!$F$39:$K$52,6,FALSE),"ONBOARDING")="ACTIVE",'Розрахунок'!H13,"") -> 0 | I13: =IF(IFERROR(VLOOKUP($A13,'Налаштування'!$F$39:$K$52,6,FALSE),"ONBOARDING")="ACTIVE",'Розрахунок'!J13,"—") -> — | J13: =IF(IFERROR(VLOOKUP($A13,'Налаштування'!$F$39:$K$52,6,FALSE),"ONBOARDING")="ACTIVE",'Розрахунок'!K13,"—") -> — | K13: {=IF(IFERROR(VLOOKUP($A13,'Налаштування'!$F$39:$K$52,6,FALSE),"ONBOARDING")="ACTIVE",INDEX('Оперативна оцінка'!$B$24:$N$24,1,MATCH($A13,'Оперативна оцінка'!$B$4:$N$4,0)),"")} | L13: =IFERROR(__xludf.DUMMYFUNCTION("IFERROR(MAX(FILTER(DATEVALUE('Реєстр'!$D$2:$D$5000),'Реєстр'!$B$2:$B$5000=$A13,'Реєстр'!$C$2:$C$5000=""Балістика / швидкісні ракети"",REGEXMATCH('Реєстр'!$AC$2:$AC$5000,""^Включено""))),""—"")"),46114.0) -> 46114 | M13: =IF(IFERROR(VLOOKUP($A13,'Налаштування'!$F$39:$K$52,6,FALSE),"ONBOARDING")="ACTIVE",'Розрахунок'!O13,"") -> 0/8 • 1/52 | N13: =IF(IFERROR(VLOOKUP($A13,'Налаштування'!$F$39:$K$52,6,FALSE),"ONBOARDING")="ACTIVE",TEXT('Розрахунок'!Q13,"0.0%")&"–"&TEXT('Розрахунок'!R13,"0.0%"),"") -> 0,3%–10,1% | O13: =IF(IFERROR(VLOOKUP($A13,'Налаштування'!$F$39:$K$52,6,FALSE),"ONBOARDING")="ACTIVE",'Розрахунок'!S13,"") -> 0.019230769 | P13: =IFERROR("2src "&TEXT(COUNTIFS('Реєстр'!$B$2:$B$5000,$A13,'Реєстр'!$C$2:$C$5000,"Балістика / швидкісні ракети",'Реєстр'!$AC$2:$AC$5000,"Включено*",'Реєстр'!$AR$2:$AR$5000,"MODEL-365",'Реєстр'!$O$2:$O$5000,"<>")/COUNTIFS('Реєстр'!$B$2:$B$5000,$A13,'Реєстр'!$C$2:$C$5000,"Балістика / швидкісні ракети",'Реєстр'!$AC$2:$AC$5000,"Включено*",'Реєстр'!$AR$2:$AR$5000,"MODEL-365"),"0%")&" • B "&TEXT(COUNTIFS('Реєстр'!$B$2:$B$5000,$A13,'Реєстр'!$C$2:$C$5000,"Балістика / швидкісні ракети",'Реєстр'!$AC$2:$AC$5000,"Включено*",'Реєстр'!$AR$2:$AR$5000,"MODEL-365",'Реєстр'!$L$2:$L$5000,"B*")/COUNTIFS('Реєстр'!$B$2:$B$5000,$A13,'Реєстр'!$C$2:$C$5000,"Балістика / швидкісні ракети",'Реєстр'!$AC$2:$AC$5000,"Включено*",'Реєстр'!$AR$2:$AR$5000,"MODEL-365"),"0%"),"—") -> 2src 100% • B 0%
A14: ='Налаштування'!R48 -> Кривий Ріг | B14: =IF(IFERROR(VLOOKUP($A14,'Налаштування'!$F$39:$K$52,6,FALSE),"ONBOARDING")="ACTIVE",'Розрахунок'!B14,"") -> 0 | C14: =IF(IFERROR(VLOOKUP($A14,'Налаштування'!$F$39:$K$52,6,FALSE),"ONBOARDING")="ACTIVE",'Розрахунок'!C14,"") -> 0 | D14: =IF(IFERROR(VLOOKUP($A14,'Налаштування'!$F$39:$K$52,6,FALSE),"ONBOARDING")="ACTIVE",'Розрахунок'!D14,"") -> 0 | E14: =IF(IFERROR(VLOOKUP($A14,'Налаштування'!$F$39:$K$52,6,FALSE),"ONBOARDING")="ACTIVE",'Розрахунок'!E14,"") -> 0.019230769 | F14: =IF(IFERROR(VLOOKUP($A14,'Налаштування'!$F$39:$K$52,6,FALSE),"ONBOARDING")="ACTIVE",'Розрахунок'!F14,"") -> 0.025545057 | G14: =IF(IFERROR(VLOOKUP($A14,'Налаштування'!$F$39:$K$52,6,FALSE),"ONBOARDING")="ACTIVE",'Розрахунок'!G14,"BACKFILL 365") -> Немає | H14: =IF(IFERROR(VLOOKUP($A14,'Налаштування'!$F$39:$K$52,6,FALSE),"ONBOARDING")="ACTIVE",'Розрахунок'!H14,"") -> 0 | I14: =IF(IFERROR(VLOOKUP($A14,'Налаштування'!$F$39:$K$52,6,FALSE),"ONBOARDING")="ACTIVE",'Розрахунок'!J14,"—") -> — | J14: =IF(IFERROR(VLOOKUP($A14,'Налаштування'!$F$39:$K$52,6,FALSE),"ONBOARDING")="ACTIVE",'Розрахунок'!K14,"—") -> — | K14: {=IF(IFERROR(VLOOKUP($A14,'Налаштування'!$F$39:$K$52,6,FALSE),"ONBOARDING")="ACTIVE",INDEX('Оперативна оцінка'!$B$24:$N$24,1,MATCH($A14,'Оперативна оцінка'!$B$4:$N$4,0)),"")} | L14: =IFERROR(__xludf.DUMMYFUNCTION("IFERROR(MAX(FILTER(DATEVALUE('Реєстр'!$D$2:$D$5000),'Реєстр'!$B$2:$B$5000=$A14,'Реєстр'!$C$2:$C$5000=""Балістика / швидкісні ракети"",REGEXMATCH('Реєстр'!$AC$2:$AC$5000,""^Включено""))),""—"")"),46287.0) -> 46287 | M14: =IF(IFERROR(VLOOKUP($A14,'Налаштування'!$F$39:$K$52,6,FALSE),"ONBOARDING")="ACTIVE",'Розрахунок'!O14,"") -> 0/8 • 1/52 | N14: =IF(IFERROR(VLOOKUP($A14,'Налаштування'!$F$39:$K$52,6,FALSE),"ONBOARDING")="ACTIVE",TEXT('Розрахунок'!Q14,"0.0%")&"–"&TEXT('Розрахунок'!R14,"0.0%"),"") -> 0,3%–10,1% | O14: =IF(IFERROR(VLOOKUP($A14,'Налаштування'!$F$39:$K$52,6,FALSE),"ONBOARDING")="ACTIVE",'Розрахунок'!S14,"") -> 0.019230769 | P14: =IFERROR(__xludf.DUMMYFUNCTION("IF(IFERROR(VLOOKUP($A14,'Налаштування'!$F$39:$K$52,6,FALSE),""ONBOARDING"")=""ACTIVE"",IF(COUNTIFS('Реєстр'!$B$2:$B$5000,$A14,'Реєстр'!$C$2:$C$5000,""Балістика / швидкісні ракети"",'Реєстр'!$AC$2:$AC$5000,""Включено*"",'Реєстр'!$AR$2:$AR$5000,""MODEL-365"&""")=0,""0 positives • 365D covered"",""2src ""&TEXT(COUNTIFS('Реєстр'!$B$2:$B$5000,$A14,'Реєстр'!$C$2:$C$5000,""Балістика / швидкісні ракети"",'Реєстр'!$AC$2:$AC$5000,""Включено*"",'Реєстр'!$AR$2:$AR$5000,""MODEL-365"",'Реєстр'!$O$2:$O$5000,""<>"")/COUNTI"&"FS('Реєстр'!$B$2:$B$5000,$A14,'Реєстр'!$C$2:$C$5000,""Балістика / швидкісні ракети"",'Реєстр'!$AC$2:$AC$5000,""Включено*"",'Реєстр'!$AR$2:$AR$5000,""MODEL-365""),""0%"")),""audit ""&IFERROR(ROWS(UNIQUE(FILTER('Аудит покриття'!$A$2:$A$6905,'Аудит покриття'"&"!$B$2:$B$6905=$A14,'Аудит покриття'!$C$2:$C$6905=""VERIFIED""))),0)&""/365 • scoring OFF"")"),"2src 100%") -> 2src 100%
A15: ='Налаштування'!R49 -> Павлоград | B15: =IF(IFERROR(VLOOKUP($A15,'Налаштування'!$F$39:$K$52,6,FALSE),"ONBOARDING")="ACTIVE",'Розрахунок'!B15,"") -> 0 | C15: =IF(IFERROR(VLOOKUP($A15,'Налаштування'!$F$39:$K$52,6,FALSE),"ONBOARDING")="ACTIVE",'Розрахунок'!C15,"") -> 0 | D15: =IF(IFERROR(VLOOKUP($A15,'Налаштування'!$F$39:$K$52,6,FALSE),"ONBOARDING")="ACTIVE",'Розрахунок'!D15,"") -> 0 | E15: =IF(IFERROR(VLOOKUP($A15,'Налаштування'!$F$39:$K$52,6,FALSE),"ONBOARDING")="ACTIVE",'Розрахунок'!E15,"") -> 0 | F15: =IF(IFERROR(VLOOKUP($A15,'Налаштування'!$F$39:$K$52,6,FALSE),"ONBOARDING")="ACTIVE",'Розрахунок'!F15,"") -> 0.0038013929 | G15: =IF(IFERROR(VLOOKUP($A15,'Налаштування'!$F$39:$K$52,6,FALSE),"ONBOARDING")="ACTIVE",'Розрахунок'!G15,"BACKFILL 365") -> Немає | H15: =IF(IFERROR(VLOOKUP($A15,'Налаштування'!$F$39:$K$52,6,FALSE),"ONBOARDING")="ACTIVE",'Розрахунок'!H15,"") -> 0 | I15: =IF(IFERROR(VLOOKUP($A15,'Налаштування'!$F$39:$K$52,6,FALSE),"ONBOARDING")="ACTIVE",'Розрахунок'!J15,"—") -> — | J15: =IF(IFERROR(VLOOKUP($A15,'Налаштування'!$F$39:$K$52,6,FALSE),"ONBOARDING")="ACTIVE",'Розрахунок'!K15,"—") -> — | K15: {=IF(IFERROR(VLOOKUP($A15,'Налаштування'!$F$39:$K$52,6,FALSE),"ONBOARDING")="ACTIVE",INDEX('Оперативна оцінка'!$B$24:$N$24,1,MATCH($A15,'Оперативна оцінка'!$B$4:$N$4,0)),"")} | L15: =IFERROR(__xludf.DUMMYFUNCTION("IFERROR(MAX(FILTER(DATEVALUE('Реєстр'!$D$2:$D$5000),'Реєстр'!$B$2:$B$5000=$A15,'Реєстр'!$C$2:$C$5000=""Балістика / швидкісні ракети"",REGEXMATCH('Реєстр'!$AC$2:$AC$5000,""^Включено""))),""—"")"),46287.0) -> 46287 | M15: =IF(IFERROR(VLOOKUP($A15,'Налаштування'!$F$39:$K$52,6,FALSE),"ONBOARDING")="ACTIVE",'Розрахунок'!O15,"") -> 0/8 • 0/52 | N15: =IF(IFERROR(VLOOKUP($A15,'Налаштування'!$F$39:$K$52,6,FALSE),"ONBOARDING")="ACTIVE",TEXT('Розрахунок'!Q15,"0.0%")&"–"&TEXT('Розрахунок'!R15,"0.0%"),"") -> 0,0%–6,9% | O15: =IF(IFERROR(VLOOKUP($A15,'Налаштування'!$F$39:$K$52,6,FALSE),"ONBOARDING")="ACTIVE",'Розрахунок'!S15,"") -> 0 | P15: =IFERROR(__xludf.DUMMYFUNCTION("IF(IFERROR(VLOOKUP($A15,'Налаштування'!$F$39:$K$52,6,FALSE),""ONBOARDING"")=""ACTIVE"",IF(COUNTIFS('Реєстр'!$B$2:$B$5000,$A15,'Реєстр'!$C$2:$C$5000,""Балістика / швидкісні ракети"",'Реєстр'!$AC$2:$AC$5000,""Включено*"",'Реєстр'!$AR$2:$AR$5000,""MODEL-365"&""")=0,""0 positives • 365D covered"",""2src ""&TEXT(COUNTIFS('Реєстр'!$B$2:$B$5000,$A15,'Реєстр'!$C$2:$C$5000,""Балістика / швидкісні ракети"",'Реєстр'!$AC$2:$AC$5000,""Включено*"",'Реєстр'!$AR$2:$AR$5000,""MODEL-365"",'Реєстр'!$O$2:$O$5000,""<>"")/COUNTI"&"FS('Реєстр'!$B$2:$B$5000,$A15,'Реєстр'!$C$2:$C$5000,""Балістика / швидкісні ракети"",'Реєстр'!$AC$2:$AC$5000,""Включено*"",'Реєстр'!$AR$2:$AR$5000,""MODEL-365""),""0%"")),""audit ""&IFERROR(ROWS(UNIQUE(FILTER('Аудит покриття'!$A$2:$A$6905,'Аудит покриття'"&"!$B$2:$B$6905=$A15,'Аудит покриття'!$C$2:$C$6905=""VERIFIED""))),0)&""/365 • scoring OFF"")"),"2src 100%") -> 2src 100%
A16: ='Налаштування'!R50 -> Полтава | B16: =IF(IFERROR(VLOOKUP($A16,'Налаштування'!$F$39:$K$52,6,FALSE),"ONBOARDING")="ACTIVE",'Розрахунок'!B16,"") -> 0 | C16: =IF(IFERROR(VLOOKUP($A16,'Налаштування'!$F$39:$K$52,6,FALSE),"ONBOARDING")="ACTIVE",'Розрахунок'!C16,"") -> 0 | D16: =IF(IFERROR(VLOOKUP($A16,'Налаштування'!$F$39:$K$52,6,FALSE),"ONBOARDING")="ACTIVE",'Розрахунок'!D16,"") -> 0 | E16: =IF(IFERROR(VLOOKUP($A16,'Налаштування'!$F$39:$K$52,6,FALSE),"ONBOARDING")="ACTIVE",'Розрахунок'!E16,"") -> 0 | F16: =IF(IFERROR(VLOOKUP($A16,'Налаштування'!$F$39:$K$52,6,FALSE),"ONBOARDING")="ACTIVE",'Розрахунок'!F16,"") -> 0.0091047491 | G16: =IF(IFERROR(VLOOKUP($A16,'Налаштування'!$F$39:$K$52,6,FALSE),"ONBOARDING")="ACTIVE",'Розрахунок'!G16,"BACKFILL 365") -> Немає | H16: =IF(IFERROR(VLOOKUP($A16,'Налаштування'!$F$39:$K$52,6,FALSE),"ONBOARDING")="ACTIVE",'Розрахунок'!H16,"") -> 0 | I16: =IF(IFERROR(VLOOKUP($A16,'Налаштування'!$F$39:$K$52,6,FALSE),"ONBOARDING")="ACTIVE",'Розрахунок'!J16,"—") -> — | J16: =IF(IFERROR(VLOOKUP($A16,'Налаштування'!$F$39:$K$52,6,FALSE),"ONBOARDING")="ACTIVE",'Розрахунок'!K16,"—") -> — | K16: {=IF(IFERROR(VLOOKUP($A16,'Налаштування'!$F$39:$K$52,6,FALSE),"ONBOARDING")="ACTIVE",INDEX('Оперативна оцінка'!$B$24:$N$24,1,MATCH($A16,'Оперативна оцінка'!$B$4:$N$4,0)),"")} | L16: =IFERROR(__xludf.DUMMYFUNCTION("IFERROR(MAX(FILTER(DATEVALUE('Реєстр'!$D$2:$D$5000),'Реєстр'!$B$2:$B$5000=$A16,'Реєстр'!$C$2:$C$5000=""Балістика / швидкісні ракети"",REGEXMATCH('Реєстр'!$AC$2:$AC$5000,""^Включено""))),""—"")"),46204.0) -> 46204 | M16: =IF(IFERROR(VLOOKUP($A16,'Налаштування'!$F$39:$K$52,6,FALSE),"ONBOARDING")="ACTIVE",'Розрахунок'!O16,"") -> 0/6 • 0/50 | N16: =IF(IFERROR(VLOOKUP($A16,'Налаштування'!$F$39:$K$52,6,FALSE),"ONBOARDING")="ACTIVE",TEXT('Розрахунок'!Q16,"0.0%")&"–"&TEXT('Розрахунок'!R16,"0.0%"),"") -> 0,0%–7,1% | O16: =IF(IFERROR(VLOOKUP($A16,'Налаштування'!$F$39:$K$52,6,FALSE),"ONBOARDING")="ACTIVE",'Розрахунок'!S16,"") -> 0 | P16: =IFERROR(__xludf.DUMMYFUNCTION("IF(IFERROR(VLOOKUP($A16,'Налаштування'!$F$39:$K$52,6,FALSE),""ONBOARDING"")=""ACTIVE"",IF(COUNTIFS('Реєстр'!$B$2:$B$5000,$A16,'Реєстр'!$C$2:$C$5000,""Балістика / швидкісні ракети"",'Реєстр'!$AC$2:$AC$5000,""Включено*"",'Реєстр'!$AR$2:$AR$5000,""MODEL-365"&""")=0,""0 positives • 365D covered"",""2src ""&TEXT(COUNTIFS('Реєстр'!$B$2:$B$5000,$A16,'Реєстр'!$C$2:$C$5000,""Балістика / швидкісні ракети"",'Реєстр'!$AC$2:$AC$5000,""Включено*"",'Реєстр'!$AR$2:$AR$5000,""MODEL-365"",'Реєстр'!$O$2:$O$5000,""<>"")/COUNTI"&"FS('Реєстр'!$B$2:$B$5000,$A16,'Реєстр'!$C$2:$C$5000,""Балістика / швидкісні ракети"",'Реєстр'!$AC$2:$AC$5000,""Включено*"",'Реєстр'!$AR$2:$AR$5000,""MODEL-365""),""0%"")),""audit ""&IFERROR(ROWS(UNIQUE(FILTER('Аудит покриття'!$A$2:$A$6905,'Аудит покриття'"&"!$B$2:$B$6905=$A16,'Аудит покриття'!$C$2:$C$6905=""VERIFIED""))),0)&""/365 • scoring OFF"")"),"2src 100%") -> 2src 100%
A17: ='Налаштування'!R51 -> Суми | B17: =IF(IFERROR(VLOOKUP($A17,'Налаштування'!$F$39:$K$52,6,FALSE),"ONBOARDING")="ACTIVE",'Розрахунок'!B17,"") -> 0 | C17: =IF(IFERROR(VLOOKUP($A17,'Налаштування'!$F$39:$K$52,6,FALSE),"ONBOARDING")="ACTIVE",'Розрахунок'!C17,"") -> 0 | D17: =IF(IFERROR(VLOOKUP($A17,'Налаштування'!$F$39:$K$52,6,FALSE),"ONBOARDING")="ACTIVE",'Розрахунок'!D17,"") -> 0 | E17: =IF(IFERROR(VLOOKUP($A17,'Налаштування'!$F$39:$K$52,6,FALSE),"ONBOARDING")="ACTIVE",'Розрахунок'!E17,"") -> 0 | F17: =IF(IFERROR(VLOOKUP($A17,'Налаштування'!$F$39:$K$52,6,FALSE),"ONBOARDING")="ACTIVE",'Розрахунок'!F17,"") -> 0.000358165 | G17: ='Розрахунок'!G17 -> Немає | H17: =IF(IFERROR(VLOOKUP($A17,'Налаштування'!$F$39:$K$52,6,FALSE),"ONBOARDING")="ACTIVE",'Розрахунок'!H17,"") -> 0 | I17: =IF(IFERROR(VLOOKUP($A17,'Налаштування'!$F$39:$K$52,6,FALSE),"ONBOARDING")="ACTIVE",'Розрахунок'!J17,"—") -> — | J17: =IF(IFERROR(VLOOKUP($A17,'Налаштування'!$F$39:$K$52,6,FALSE),"ONBOARDING")="ACTIVE",'Розрахунок'!K17,"—") -> — | K17: {=IF(IFERROR(VLOOKUP($A17,'Налаштування'!$F$39:$K$52,6,FALSE),"ONBOARDING")="ACTIVE",INDEX('Оперативна оцінка'!$B$24:$N$24,1,MATCH($A17,'Оперативна оцінка'!$B$4:$N$4,0)),"")} | L17: =IFERROR(__xludf.DUMMYFUNCTION("IFERROR(MAX(FILTER(DATEVALUE('Реєстр'!$D$2:$D$5000),'Реєстр'!$B$2:$B$5000=$A17,'Реєстр'!$C$2:$C$5000=""Балістика / швидкісні ракети"",REGEXMATCH('Реєстр'!$AC$2:$AC$5000,""^Включено""))),""—"")"),45975.0) -> 45975 | M17: =IF(IFERROR(VLOOKUP($A17,'Налаштування'!$F$39:$K$52,6,FALSE),"ONBOARDING")="ACTIVE",'Розрахунок'!O17,"") -> 0/8 • 0/52 | N17: =IF(IFERROR(VLOOKUP($A17,'Налаштування'!$F$39:$K$52,6,FALSE),"ONBOARDING")="ACTIVE",TEXT('Розрахунок'!Q17,"0.0%")&"–"&TEXT('Розрахунок'!R17,"0.0%"),"") -> 0,0%–6,9% | O17: =IF(IFERROR(VLOOKUP($A17,'Налаштування'!$F$39:$K$52,6,FALSE),"ONBOARDING")="ACTIVE",'Розрахунок'!S17,"") -> 0 | P17: =IFERROR(__xludf.DUMMYFUNCTION("IF(IFERROR(VLOOKUP($A17,'Налаштування'!$F$39:$K$52,6,FALSE),""ONBOARDING"")=""ACTIVE"",IF(COUNTIFS('Реєстр'!$B$2:$B$5000,$A17,'Реєстр'!$C$2:$C$5000,""Балістика / швидкісні ракети"",'Реєстр'!$AC$2:$AC$5000,""Включено*"",'Реєстр'!$AR$2:$AR$5000,""MODEL-365"&""")=0,""0 positives • 365D covered"",""2src ""&TEXT(COUNTIFS('Реєстр'!$B$2:$B$5000,$A17,'Реєстр'!$C$2:$C$5000,""Балістика / швидкісні ракети"",'Реєстр'!$AC$2:$AC$5000,""Включено*"",'Реєстр'!$AR$2:$AR$5000,""MODEL-365"",'Реєстр'!$O$2:$O$5000,""<>"")/COUNTI"&"FS('Реєстр'!$B$2:$B$5000,$A17,'Реєстр'!$C$2:$C$5000,""Балістика / швидкісні ракети"",'Реєстр'!$AC$2:$AC$5000,""Включено*"",'Реєстр'!$AR$2:$AR$5000,""MODEL-365""),""0%"")),""audit ""&IFERROR(ROWS(UNIQUE(FILTER('Аудит покриття'!$A$2:$A$6905,'Аудит покриття'"&"!$B$2:$B$6905=$A17,'Аудит покриття'!$C$2:$C$6905=""VERIFIED""))),0)&""/365 • scoring OFF"")"),"2src 100%") -> 2src 100%
A18: ='Налаштування'!R52 -> Кременчук | B18: =IF(IFERROR(VLOOKUP($A18,'Налаштування'!$F$39:$K$52,6,FALSE),"ONBOARDING")="ACTIVE",'Розрахунок'!B18,"") -> 0 | C18: =IF(IFERROR(VLOOKUP($A18,'Налаштування'!$F$39:$K$52,6,FALSE),"ONBOARDING")="ACTIVE",'Розрахунок'!C18,"") -> 0 | D18: =IF(IFERROR(VLOOKUP($A18,'Налаштування'!$F$39:$K$52,6,FALSE),"ONBOARDING")="ACTIVE",'Розрахунок'!D18,"") -> 0 | E18: =IF(IFERROR(VLOOKUP($A18,'Налаштування'!$F$39:$K$52,6,FALSE),"ONBOARDING")="ACTIVE",'Розрахунок'!E18,"") -> 0 | F18: =IF(IFERROR(VLOOKUP($A18,'Налаштування'!$F$39:$K$52,6,FALSE),"ONBOARDING")="ACTIVE",'Розрахунок'!F18,"") -> 0.014910861 | G18: ='Розрахунок'!G18 -> Немає | H18: =IF(IFERROR(VLOOKUP($A18,'Налаштування'!$F$39:$K$52,6,FALSE),"ONBOARDING")="ACTIVE",'Розрахунок'!H18,"") -> 0 | I18: =IF(IFERROR(VLOOKUP($A18,'Налаштування'!$F$39:$K$52,6,FALSE),"ONBOARDING")="ACTIVE",'Розрахунок'!J18,"—") -> — | J18: =IF(IFERROR(VLOOKUP($A18,'Налаштування'!$F$39:$K$52,6,FALSE),"ONBOARDING")="ACTIVE",'Розрахунок'!K18,"—") -> — | K18: {=IF(IFERROR(VLOOKUP($A18,'Налаштування'!$F$39:$K$52,6,FALSE),"ONBOARDING")="ACTIVE",INDEX('Оперативна оцінка'!$B$24:$O$24,1,MATCH($A18,'Оперативна оцінка'!$B$4:$O$4,0)),"")} | L18: =IFERROR(__xludf.DUMMYFUNCTION("IFERROR(MAX(FILTER(DATEVALUE('Реєстр'!$D$2:$D$5000),'Реєстр'!$B$2:$B$5000=$A18,'Реєстр'!$C$2:$C$5000=""Балістика / швидкісні ракети"",REGEXMATCH('Реєстр'!$AC$2:$AC$5000,""^Включено""))),""—"")"),46302.0) -> 46302 | M18: =IF(IFERROR(VLOOKUP($A18,'Налаштування'!$F$39:$K$52,6,FALSE),"ONBOARDING")="ACTIVE",'Розрахунок'!O18,"") -> 0/6 • 0/50 | N18: =IF(IFERROR(VLOOKUP($A18,'Налаштування'!$F$39:$K$52,6,FALSE),"ONBOARDING")="ACTIVE",TEXT('Розрахунок'!Q18,"0.0%")&"–"&TEXT('Розрахунок'!R18,"0.0%"),"") -> 0,0%–7,1% | O18: =IF(IFERROR(VLOOKUP($A18,'Налаштування'!$F$39:$K$52,6,FALSE),"ONBOARDING")="ACTIVE",'Розрахунок'!S18,"") -> 0 | P18: =IFERROR(__xludf.DUMMYFUNCTION("IF(IFERROR(VLOOKUP($A18,'Налаштування'!$F$39:$K$52,6,FALSE),""ONBOARDING"")=""ACTIVE"",IF(COUNTIFS('Реєстр'!$B$2:$B$5000,$A18,'Реєстр'!$C$2:$C$5000,""Балістика / швидкісні ракети"",'Реєстр'!$AC$2:$AC$5000,""Включено*"",'Реєстр'!$AR$2:$AR$5000,""MODEL-365"&""")=0,""0 positives • 365D covered"",""2src ""&TEXT(COUNTIFS('Реєстр'!$B$2:$B$5000,$A18,'Реєстр'!$C$2:$C$5000,""Балістика / швидкісні ракети"",'Реєстр'!$AC$2:$AC$5000,""Включено*"",'Реєстр'!$AR$2:$AR$5000,""MODEL-365"",'Реєстр'!$O$2:$O$5000,""<>"")/COUNTI"&"FS('Реєстр'!$B$2:$B$5000,$A18,'Реєстр'!$C$2:$C$5000,""Балістика / швидкісні ракети"",'Реєстр'!$AC$2:$AC$5000,""Включено*"",'Реєстр'!$AR$2:$AR$5000,""MODEL-365""),""0%"")),""audit ""&IFERROR(ROWS(UNIQUE(FILTER('Аудит покриття'!$A$2:$A$6905,'Аудит покриття'"&"!$B$2:$B$6905=$A18,'Аудит покриття'!$C$2:$C$6905=""VERIFIED""))),0)&""/365 • scoring OFF"")"),"2src 100%") -> 2src 100%
A19: Метод | B19: R56/R90/R180/R365 — raw same-weekday rates. Smoothed base = 50% all-day decay + 50% weekday decay, half-life 90 днів. Домінантний день лишається окремим режимним сигналом.
A20: Режим | B20: Домінантний день режиму — це найчастіший день балістичних attack-days за останні 56 днів. Він не замінює день, для якого зараз рахується %. Цільовий % завжди рахується для дня після 00:00 у поточній ночі.
A21: Невизначеність | B21: 95% CI показує статистичну невизначеність R365 для цільового дня тижня. Support = кількість attack-days / covered occurrences. Це не інтервал для оперативного прогнозу.
A22: Evidence | B22: Model-selection evidence: 4 core cities on historical walk-forward. Expanded ACTIVE cities inherit the frozen v2.1-shrink specification but are not treated as independently validated until prospective backtest accumulates.
A23: Walk-forward | B23: Model selection заморожена на історичній валідації 4 core-моделей: 50/50 shrink + HL90. Суми та Кременчук мають повний 365D calendar + 365D walk-forward/backcast і входять як ACTIVE_EXTENDED після проходження onboarding gate; prospective якість оцінюється новими VALID_PRE_EVENT ночами.
A24: Global cycle | B24: Weekly anchor поки лишається контекстом: 01.08–24.09 pooled attack-rate 12,5% в anchor-дні проти 10,1% в інші дні (RR 1,24x), з різним напрямом по містах. Автоматичної поправки до % немає.
A25: Версія | B25: v2.1-shrink: historical base = 50% weekday decay HL90 + 50% all-day decay HL90. Оперативний % лишається окремим шаром і не підміняється статистичною базою.
A27: MODEL STATUS
A28: Layer | B28: Version | C28: State | D28: Live nights | E28: Gate | F28: Evidence
A29: Historical base | B29: ='Контроль моделі'!B160 -> v2.1-shrink | C29: ='Контроль моделі'!C160 -> VALIDATED / FROZEN | D29: ='Контроль моделі'!D160 -> 1 | E29: ='Контроль моделі'!E160 -> ≥30 new resolved nights before any re-fit | F29: WF90D + 60/30 holdout; 50/50 frozen
A30: Operational layer | B30: ='Контроль моделі'!B161 -> ops-v0 | C30: ='Контроль моделі'!C161 -> COLLECTING DATA | D30: ='Контроль моделі'!D161 -> 1 | E30: ='Контроль моделі'!E161 -> ≥30 resolved OPS_FINAL nights + ≥80% complete factor rows | F30: ='Контроль моделі'!F161 -> factor completeness: 91%
A31: Live backtest | B31: ='Контроль моделі'!B162 -> immutable snapshots | C31: ='Контроль моделі'!C162 -> ACTIVE | D31: ='Контроль моделі'!D162 -> 1 | E31: ='Контроль моделі'!E162 -> VALID_PRE_EVENT only | F31: ='Контроль моделі'!F162 -> LATE_DIAGNOSTIC та LEGACY ніколи не входять у score.
A33: DAILY CYCLE
A34: Крок | B34: Дата | C34: Статус / результат | D34: Міста | E34: Наступна дія | F34: Примітка
A35: Останній аудит | B35: ='Розрахунок'!K2 -> 46297 | C35: =IFERROR(__xludf.DUMMYFUNCTION("""Балістика: ""&SUMPRODUCT(('Аудит покриття'!$A$2:$A$7600='Розрахунок'!K2)*('Аудит покриття'!$C$2:$C$7600=""VERIFIED"")*N(REGEXMATCH('Аудит покриття'!$B$2:$B$7600,""^(""&TEXTJOIN(""|"",TRUE,FILTER('Налаштування'!$F$39:$F$100,'Налаштування'!$K$39:$K$100="""&"ACTIVE""))&"")$""))*'Аудит покриття'!$D$2:$D$7600)&"" attack-days / ""&SUMPRODUCT(('Аудит покриття'!$A$2:$A$7600='Розрахунок'!K2)*('Аудит покриття'!$C$2:$C$7600=""VERIFIED"")*N(REGEXMATCH('Аудит покриття'!$B$2:$B$7600,""^(""&TEXTJOIN(""|"",TRUE,FILTER('На"&"лаштування'!$F$39:$F$100,'Налаштування'!$K$39:$K$100=""ACTIVE""))&"")$"")))&"" audit-verified models"""),"Балістика: 1 attack-days / 14 audit-verified models") -> Балістика: 1 attack-days / 14 audit-verified models | D35: =IFERROR(__xludf.DUMMYFUNCTION("TEXTJOIN("", "",TRUE,FILTER('Аудит покриття'!$B$2:$B$7600,'Аудит покриття'!$A$2:$A$7600='Розрахунок'!K2,'Аудит покриття'!$C$2:$C$7600=""VERIFIED"",REGEXMATCH('Аудит покриття'!$B$2:$B$7600,""^(""&TEXTJOIN(""|"",TRUE,FILTER('Налаштування'!$F$39:$F$100,'Нала"&"штування'!$K$39:$K$100=""ACTIVE""))&"")$"")))"),"Київ, Дніпро, Житомир, Запоріжжя, Миколаїв, Одеса, Харків, Херсон, Чернігів, Кривий Ріг, Павлоград, Полтава, Суми, Кременчук") -> Київ, Дніпро, Житомир, Запоріжжя, Миколаїв, Одеса, Харків, Херсон, Чернігів, Кривий Ріг, Павлоград, Полтава, Суми, Кременчук | E35: Закрито | F35: Audit-required і scoreable розділені. Суми завершили 365D backfill та ACTIVE; Житомир має live-audit start 29.09.
A36: Наступний STAT_20 | B36: ='Розрахунок'!B2 -> 46307 | C36: =IF(MOD(NOW(),1)<TIME(20,0,0),"сьогодні о 20:00","готовий / вже настав") -> сьогодні о 20:00 | D36: =COUNTIF('Налаштування'!K39:K100,"ACTIVE")&" ACTIVE scoreable" -> 14 ACTIVE scoreable | E36: Зафіксувати pre-event snapshot | F36: Цільова дата після 00:00.
A37: Цільова ніч | B37: ='Розрахунок'!B2 -> 46307 | C37: =CHOOSE(WEEKDAY('Розрахунок'!B2-1,2),"ПН","ВТ","СР","ЧТ","ПТ","СБ","НД")&"→"&CHOOSE(WEEKDAY('Розрахунок'!B2,2),"ПН","ВТ","СР","ЧТ","ПТ","СБ","НД") -> НД→ПН | D37: =COUNTA('Налаштування'!F39:F100)&" моделей ("&COUNTIF('Налаштування'!K39:K100,"ACTIVE")&" scoreable)" -> 14 моделей (14 scoreable) | E37: Після STAT_20 — OPS_FINAL | F37: Для цієї дати historical base буде оновлена автоматично.
A38: Наступний аудит | B38: ='Розрахунок'!K2+1 -> 46298 | C38: =IF('Розрахунок'!K2+1=TODAY(),"AUDIT_TODAY",IF('Розрахунок'!K2+1<TODAY(),"PENDING","FUTURE")) -> PENDING | D38: =COUNTA('Налаштування'!F39:F100)&" registered / live-audit models" -> 14 registered / live-audit models | E38: Після завершення ночі | F38: Cutoff рухається тільки після VERIFIED audit.
D39: =COUNTIF('Налаштування'!K39:K100,"ACTIVE")&" ACTIVE + "&COUNTIF('Налаштування'!K39:K100,"ONBOARDING")&" onboarding" -> 14 ACTIVE + 0 onboarding

Sheet Оперативна оцінка
A1: BADK LIVE — ОПЕРАТИВНА ОЦІНКА
A2: Цільова дата | B2: ='Розрахунок'!B2 -> 46307 | D2: День | E2: ='Розрахунок'!B3 -> Понеділок
A4: Фактор | B4: ='Налаштування'!R39 -> Київ | C4: ='Налаштування'!R40 -> Дніпро | D4: ='Налаштування'!R41 -> Житомир | E4: ='Налаштування'!R42 -> Запоріжжя | F4: ='Налаштування'!R43 -> Миколаїв | G4: ='Налаштування'!R44 -> Одеса | H4: ='Налаштування'!R45 -> Харків | I4: ='Налаштування'!R46 -> Херсон | J4: ='Налаштування'!R47 -> Чернігів | K4: ='Налаштування'!R48 -> Кривий Ріг | L4: ='Налаштування'!R49 -> Павлоград | M4: ='Налаштування'!R50 -> Полтава | N4: ='Налаштування'!R51 -> Суми | O4: ='Налаштування'!R52 -> Кременчук | P4: Примітка
A5: Smoothed base 50/50 (авто) | B5: {=IF(IFERROR(VLOOKUP(B$4,'Налаштування'!$F$39:$K$100,6,FALSE),"ONBOARDING")="ACTIVE",INDEX('Розрахунок'!$F$5:$F$17,MATCH(B$4,'Розрахунок'!$A$5:$A$17,0)),"")} -> 0.11679186 | C5: {=IF(IFERROR(VLOOKUP(C$4,'Налаштування'!$F$39:$K$100,6,FALSE),"ONBOARDING")="ACTIVE",INDEX('Розрахунок'!$F$5:$F$17,MATCH(C$4,'Розрахунок'!$A$5:$A$17,0)),"")} -> 0.049345885 | D5: {=IF(IFERROR(VLOOKUP(D$4,'Налаштування'!$F$39:$K$100,6,FALSE),"ONBOARDING")="ACTIVE",INDEX('Розрахунок'!$F$5:$F$17,MATCH(D$4,'Розрахунок'!$A$5:$A$17,0)),"")} -> 0.00029077646 | E5: {=IF(IFERROR(VLOOKUP(E$4,'Налаштування'!$F$39:$K$100,6,FALSE),"ONBOARDING")="ACTIVE",INDEX('Розрахунок'!$F$5:$F$17,MATCH(E$4,'Розрахунок'!$A$5:$A$17,0)),"")} -> 0.026823138 | F5: {=IF(IFERROR(VLOOKUP(F$4,'Налаштування'!$F$39:$K$100,6,FALSE),"ONBOARDING")="ACTIVE",INDEX('Розрахунок'!$F$5:$F$17,MATCH(F$4,'Розрахунок'!$A$5:$A$17,0)),"")} -> 0.0089819532 | G5: {=IF(IFERROR(VLOOKUP(G$4,'Налаштування'!$F$39:$K$100,6,FALSE),"ONBOARDING")="ACTIVE",INDEX('Розрахунок'!$F$5:$F$17,MATCH(G$4,'Розрахунок'!$A$5:$A$17,0)),"")} -> 0.061666566 | H5: {=IF(IFERROR(VLOOKUP(H$4,'Налаштування'!$F$39:$K$100,6,FALSE),"ONBOARDING")="ACTIVE",INDEX('Розрахунок'!$F$5:$F$17,MATCH(H$4,'Розрахунок'!$A$5:$A$17,0)),"")} -> 0.042414339 | I5: {=IF(IFERROR(VLOOKUP(I$4,'Налаштування'!$F$39:$K$100,6,FALSE),"ONBOARDING")="ACTIVE",INDEX('Розрахунок'!$F$5:$F$17,MATCH(I$4,'Розрахунок'!$A$5:$A$17,0)),"")} -> 0 | ... N5: {=IF(IFERROR(VLOOKUP(N$4,'Налаштування'!$F$39:$K$100,6,FALSE),"ONBOARDING")="ACTIVE",INDEX('Розрахунок'!$F$5:$F$17,MATCH(N$4,'Розрахунок'!$A$5:$A$17,0)),"")} -> 0.000358165 | O5: {=IF(IFERROR(VLOOKUP(O$4,'Налаштування'!$F$39:$K$100,6,FALSE),"ONBOARDING")="ACTIVE",INDEX('Розрахунок'!$F$5:$F$18,MATCH(O$4,'Розрахунок'!$A$5:$A$18,0)),"")} -> 0.014910861 | P5: ="Historical base: "&TEXT('Налаштування'!$G$6,"0%")&" weekday decay + "&TEXT('Налаштування'!$G$7,"0%")&" all-day decay; half-life "&'Налаштування'!$G$3&" днів." -> Historical base: 50% weekday decay + 50% all-day decay; half-life 90 днів.
A6: New test % | B6: =IFERROR(__xludf.DUMMYFUNCTION("LET(base,IF(IFERROR(VLOOKUP(B$4,'Налаштування'!$F$39:$K$100,6,FALSE),""ONBOARDING"")<>""ACTIVE"","""",IF(B$4<>""Київ"",B5,LET(dd,'Розрахунок'!$B$2,ww,'Розрахунок'!$B$3,cc,B$4,nn,COUNTIFS('Календар 365'!$A$2:$A$5111,"">=""&dd-365,'Календар 365'!$A$2:$A$511"&"1,""<""&dd,'Календар 365'!$B$2:$B$5111,ww,'Календар 365'!$C$2:$C$5111,cc,'Календар 365'!$D$2:$D$5111,""SYSTEMATIC_OSINT_V1""),shorta,IFERROR(SUM(FILTER(VALUE('Календар 365'!$E$2:$E$5111)*EXP(-LN(2)*(dd-'Календар 365'!$A$2:$A$5111)/30),'Календар 365'!$A$2:"&"$A$5111>=dd-365,'Календар 365'!$A$2:$A$5111<dd,'Календар 365'!$B$2:$B$5111=ww,'Календар 365'!$C$2:$C$5111=cc,'Календар 365'!$D$2:$D$5111=""SYSTEMATIC_OSINT_V1""))/SUM(FILTER(EXP(-LN(2)*(dd-'Календар 365'!$A$2:$A$5111)/30),'Календар 365'!$A$2:$A$5111>=dd-3"&"65,'Календар 365'!$A$2:$A$5111<dd,'Календар 365'!$B$2:$B$5111=ww,'Календар 365'!$C$2:$C$5111=cc,'Календар 365'!$D$2:$D$5111=""SYSTEMATIC_OSINT_V1"")),0),shortb,IFERROR(SUM(FILTER(VALUE('Календар 365'!$E$2:$E$5111)*EXP(-LN(2)*(dd-'Календар 365'!$A$2:$A$511"&"1)/60),'Календар 365'!$A$2:$A$5111>=dd-365,'Календар 365'!$A$2:$A$5111<dd,'Календар 365'!$B$2:$B$5111=ww,'Календар 365'!$C$2:$C$5111=cc,'Календар 365'!$D$2:$D$5111=""SYSTEMATIC_OSINT_V1""))/SUM(FILTER(EXP(-LN(2)*(dd-'Календар 365'!$A$2:$A$5111)/60),'Кален"&"дар 365'!$A$2:$A$5111>=dd-365,'Календар 365'!$A$2:$A$5111<dd,'Календар 365'!$B$2:$B$5111=ww,'Календар 365'!$C$2:$C$5111=cc,'Календар 365'!$D$2:$D$5111=""SYSTEMATIC_OSINT_V1"")),0),allday,IFERROR(SUM(FILTER(VALUE('Календар 365'!$E$2:$E$5111)*EXP(-LN(2)*(dd"&"-'Календар 365'!$A$2:$A$5111)/90),'Календар 365'!$A$2:$A$5111>=dd-365,'Календар 365'!$A$2:$A$5111<dd,'Календар 365'!$C$2:$C$5111=cc,'Календар 365'!$D$2:$D$5111=""SYSTEMATIC_OSINT_V1""))/SUM(FILTER(EXP(-LN(2)*(dd-'Календар 365'!$A$2:$A$5111)/90),'Календар "&"365'!$A$2:$A$5111>=dd-365,'Календар 365'!$A$2:$A$5111<dd,'Календар 365'!$C$2:$C$5111=cc,'Календар 365'!$D$2:$D$5111=""SYSTEMATIC_OSINT_V1"")),0),IF(nn>=45,80%*(60%*shorta+40%*shortb)+20%*allday,B5)))),delta,0.5%*(COUNTIF(B13,""Підвищує"")+COUNTIF(B16:B22,"&"""Підвищує"")-COUNTIF(B13,""Знижує"")-COUNTIF(B16:B22,""Знижує"")),IF(base="""","""",MAX(0,MIN(1,base+delta))))"),0.06634364640078039) -> 0.066343646 | C6: =LET(base,IF(IFERROR(VLOOKUP(C$4,'Налаштування'!$F$39:$K$100,6,FALSE),"ONBOARDING")="ACTIVE",C5,""),delta,0.5%*(COUNTIF(C13,"Підвищує")+COUNTIF(C16:C22,"Підвищує")-COUNTIF(C13,"Знижує")-COUNTIF(C16:C22,"Знижує")),IF(base="","",MAX(0,MIN(1,base+delta)))) -> 0.049345885 | D6: =LET(base,IF(IFERROR(VLOOKUP(D$4,'Налаштування'!$F$39:$K$100,6,FALSE),"ONBOARDING")="ACTIVE",D5,""),delta,0.5%*(COUNTIF(D13,"Підвищує")+COUNTIF(D16:D22,"Підвищує")-COUNTIF(D13,"Знижує")-COUNTIF(D16:D22,"Знижує")),IF(base="","",MAX(0,MIN(1,base+delta)))) -> 0.00029077646 | E6: =LET(base,IF(IFERROR(VLOOKUP(E$4,'Налаштування'!$F$39:$K$100,6,FALSE),"ONBOARDING")="ACTIVE",E5,""),delta,0.5%*(COUNTIF(E13,"Підвищує")+COUNTIF(E16:E22,"Підвищує")-COUNTIF(E13,"Знижує")-COUNTIF(E16:E22,"Знижує")),IF(base="","",MAX(0,MIN(1,base+delta)))) -> 0.026823138 | F6: =LET(base,IF(IFERROR(VLOOKUP(F$4,'Налаштування'!$F$39:$K$100,6,FALSE),"ONBOARDING")="ACTIVE",F5,""),delta,0.5%*(COUNTIF(F13,"Підвищує")+COUNTIF(F16:F22,"Підвищує")-COUNTIF(F13,"Знижує")-COUNTIF(F16:F22,"Знижує")),IF(base="","",MAX(0,MIN(1,base+delta)))) -> 0.0089819532 | G6: =LET(base,IF(IFERROR(VLOOKUP(G$4,'Налаштування'!$F$39:$K$100,6,FALSE),"ONBOARDING")="ACTIVE",G5,""),delta,0.5%*(COUNTIF(G13,"Підвищує")+COUNTIF(G16:G22,"Підвищує")-COUNTIF(G13,"Знижує")-COUNTIF(G16:G22,"Знижує")),IF(base="","",MAX(0,MIN(1,base+delta)))) -> 0.061666566 | H6: =LET(base,IF(IFERROR(VLOOKUP(H$4,'Налаштування'!$F$39:$K$100,6,FALSE),"ONBOARDING")="ACTIVE",H5,""),delta,0.5%*(COUNTIF(H13,"Підвищує")+COUNTIF(H16:H22,"Підвищує")-COUNTIF(H13,"Знижує")-COUNTIF(H16:H22,"Знижує")),IF(base="","",MAX(0,MIN(1,base+delta)))) -> 0.042414339 | I6: =LET(base,IF(IFERROR(VLOOKUP(I$4,'Налаштування'!$F$39:$K$100,6,FALSE),"ONBOARDING")="ACTIVE",I5,""),delta,0.5%*(COUNTIF(I13,"Підвищує")+COUNTIF(I16:I22,"Підвищує")-COUNTIF(I13,"Знижує")-COUNTIF(I16:I22,"Знижує")),IF(base="","",MAX(0,MIN(1,base+delta)))) -> 0 | J6: =LET(base,IF(IFERROR(VLOOKUP(J$4,'Налаштування'!$F$39:$K$100,6,FALSE),"ONBOARDING")="ACTIVE",J5,""),delta,0.5%*(COUNTIF(J13,"Підвищує")+COUNTIF(J16:J22,"Підвищує")-COUNTIF(J13,"Знижує")-COUNTIF(J16:J22,"Знижує")),IF(base="","",MAX(0,MIN(1,base+delta)))) -> 0.004818431 | ... O6: =LET(base,IF(IFERROR(VLOOKUP(O$4,'Налаштування'!$F$39:$K$100,6,FALSE),"ONBOARDING")="ACTIVE",O5,""),delta,0.5%*(COUNTIF(O13,"Підвищує")+COUNTIF(O16:O22,"Підвищує")-COUNTIF(O13,"Знижує")-COUNTIF(O16:O22,"Знижує")),IF(base="","",MAX(0,MIN(1,base+delta)))) -> 0.014910861 | P6: SHADOW: Київ = HL30/60 кандидат; інші ACTIVE = Smoothed base 50/50. ±0,5 п.п. за кожне Підвищує/Знижує у рядках 13,16–22; Нейтрально/Н/Д = 0. Production не змінює.
A7: R56 поточного дня (авто) | B7: {=IF(IFERROR(VLOOKUP(B$4,'Налаштування'!$F$39:$K$100,6,FALSE),"ONBOARDING")="ACTIVE",INDEX('Розрахунок'!$B$5:$B$17,MATCH(B$4,'Розрахунок'!$A$5:$A$17,0)),"")} -> 0 | C7: {=IF(IFERROR(VLOOKUP(C$4,'Налаштування'!$F$39:$K$100,6,FALSE),"ONBOARDING")="ACTIVE",INDEX('Розрахунок'!$B$5:$B$17,MATCH(C$4,'Розрахунок'!$A$5:$A$17,0)),"")} -> 0 | D7: {=IF(IFERROR(VLOOKUP(D$4,'Налаштування'!$F$39:$K$100,6,FALSE),"ONBOARDING")="ACTIVE",INDEX('Розрахунок'!$B$5:$B$17,MATCH(D$4,'Розрахунок'!$A$5:$A$17,0)),"")} -> 0 | E7: {=IF(IFERROR(VLOOKUP(E$4,'Налаштування'!$F$39:$K$100,6,FALSE),"ONBOARDING")="ACTIVE",INDEX('Розрахунок'!$B$5:$B$17,MATCH(E$4,'Розрахунок'!$A$5:$A$17,0)),"")} -> 0 | F7: {=IF(IFERROR(VLOOKUP(F$4,'Налаштування'!$F$39:$K$100,6,FALSE),"ONBOARDING")="ACTIVE",INDEX('Розрахунок'!$B$5:$B$17,MATCH(F$4,'Розрахунок'!$A$5:$A$17,0)),"")} -> 0 | G7: {=IF(IFERROR(VLOOKUP(G$4,'Налаштування'!$F$39:$K$100,6,FALSE),"ONBOARDING")="ACTIVE",INDEX('Розрахунок'!$B$5:$B$17,MATCH(G$4,'Розрахунок'!$A$5:$A$17,0)),"")} -> 0 | H7: {=IF(IFERROR(VLOOKUP(H$4,'Налаштування'!$F$39:$K$100,6,FALSE),"ONBOARDING")="ACTIVE",INDEX('Розрахунок'!$B$5:$B$17,MATCH(H$4,'Розрахунок'!$A$5:$A$17,0)),"")} -> 0 | I7: {=IF(IFERROR(VLOOKUP(I$4,'Налаштування'!$F$39:$K$100,6,FALSE),"ONBOARDING")="ACTIVE",INDEX('Розрахунок'!$B$5:$B$17,MATCH(I$4,'Розрахунок'!$A$5:$A$17,0)),"")} -> 0 | ... N7: {=IF(IFERROR(VLOOKUP(N$4,'Налаштування'!$F$39:$K$100,6,FALSE),"ONBOARDING")="ACTIVE",INDEX('Розрахунок'!$B$5:$B$17,MATCH(N$4,'Розрахунок'!$A$5:$A$17,0)),"")} -> 0 | O7: {=IF(IFERROR(VLOOKUP(O$4,'Налаштування'!$F$39:$K$100,6,FALSE),"ONBOARDING")="ACTIVE",INDEX('Розрахунок'!$B$5:$B$18,MATCH(O$4,'Розрахунок'!$A$5:$A$18,0)),"")} -> 0 | P7: Короткий режимний сигнал для поточного дня тижня
A8: Домінантний день режиму (56д) | B8: {=IF(IFERROR(VLOOKUP(B$4,'Налаштування'!$F$39:$K$100,6,FALSE),"ONBOARDING")="ACTIVE",INDEX('Розрахунок'!$G$5:$G$17,MATCH(B$4,'Розрахунок'!$A$5:$A$17,0)),"BACKFILL 365")} -> Четвер | C8: {=IF(IFERROR(VLOOKUP(C$4,'Налаштування'!$F$39:$K$100,6,FALSE),"ONBOARDING")="ACTIVE",INDEX('Розрахунок'!$G$5:$G$17,MATCH(C$4,'Розрахунок'!$A$5:$A$17,0)),"BACKFILL 365")} -> Вівторок/Середа/Субота • по 1 (нічия) | D8: {=IF(IFERROR(VLOOKUP(D$4,'Налаштування'!$F$39:$K$100,6,FALSE),"ONBOARDING")="ACTIVE",INDEX('Розрахунок'!$G$5:$G$17,MATCH(D$4,'Розрахунок'!$A$5:$A$17,0)),"BACKFILL 365")} -> Немає | E8: {=IF(IFERROR(VLOOKUP(E$4,'Налаштування'!$F$39:$K$100,6,FALSE),"ONBOARDING")="ACTIVE",INDEX('Розрахунок'!$G$5:$G$17,MATCH(E$4,'Розрахунок'!$A$5:$A$17,0)),"BACKFILL 365")} -> Середа/Четвер • по 2 (нічия) | F8: {=IF(IFERROR(VLOOKUP(F$4,'Налаштування'!$F$39:$K$100,6,FALSE),"ONBOARDING")="ACTIVE",INDEX('Розрахунок'!$G$5:$G$17,MATCH(F$4,'Розрахунок'!$A$5:$A$17,0)),"BACKFILL 365")} -> Середа/П’ятниця • по 1 (нічия) | G8: {=IF(IFERROR(VLOOKUP(G$4,'Налаштування'!$F$39:$K$100,6,FALSE),"ONBOARDING")="ACTIVE",INDEX('Розрахунок'!$G$5:$G$17,MATCH(G$4,'Розрахунок'!$A$5:$A$17,0)),"BACKFILL 365")} -> Вівторок/Середа/Четвер • по 1 (нічия) | H8: {=IF(IFERROR(VLOOKUP(H$4,'Налаштування'!$F$39:$K$100,6,FALSE),"ONBOARDING")="ACTIVE",INDEX('Розрахунок'!$G$5:$G$17,MATCH(H$4,'Розрахунок'!$A$5:$A$17,0)),"BACKFILL 365")} -> Немає | I8: {=IF(IFERROR(VLOOKUP(I$4,'Налаштування'!$F$39:$K$100,6,FALSE),"ONBOARDING")="ACTIVE",INDEX('Розрахунок'!$G$5:$G$17,MATCH(I$4,'Розрахунок'!$A$5:$A$17,0)),"BACKFILL 365")} -> Немає | ... N8: {=IF(IFERROR(VLOOKUP(N$4,'Налаштування'!$F$39:$K$100,6,FALSE),"ONBOARDING")="ACTIVE",INDEX('Розрахунок'!$G$5:$G$17,MATCH(N$4,'Розрахунок'!$A$5:$A$17,0)),"BACKFILL 365")} -> Немає | O8: {=IF(IFERROR(VLOOKUP(O$4,'Налаштування'!$F$39:$K$100,6,FALSE),"ONBOARDING")="ACTIVE",INDEX('Розрахунок'!$G$5:$G$18,MATCH(O$4,'Розрахунок'!$A$5:$A$18,0)),"BACKFILL 365")} -> Немає | P8: City-specific домінантний день серед балістичних attack-days
A9: Сила домінанти | B9: {=IF(IFERROR(VLOOKUP(B$4,'Налаштування'!$F$39:$K$100,6,FALSE),"ONBOARDING")="ACTIVE",INDEX('Розрахунок'!$H$5:$H$17,MATCH(B$4,'Розрахунок'!$A$5:$A$17,0)),"")} -> 0.33333333 | C9: {=IF(IFERROR(VLOOKUP(C$4,'Налаштування'!$F$39:$K$100,6,FALSE),"ONBOARDING")="ACTIVE",INDEX('Розрахунок'!$H$5:$H$17,MATCH(C$4,'Розрахунок'!$A$5:$A$17,0)),"")} -> 0 | D9: {=IF(IFERROR(VLOOKUP(D$4,'Налаштування'!$F$39:$K$100,6,FALSE),"ONBOARDING")="ACTIVE",INDEX('Розрахунок'!$H$5:$H$17,MATCH(D$4,'Розрахунок'!$A$5:$A$17,0)),"")} -> 0 | E9: {=IF(IFERROR(VLOOKUP(E$4,'Налаштування'!$F$39:$K$100,6,FALSE),"ONBOARDING")="ACTIVE",INDEX('Розрахунок'!$H$5:$H$17,MATCH(E$4,'Розрахунок'!$A$5:$A$17,0)),"")} -> 0 | F9: {=IF(IFERROR(VLOOKUP(F$4,'Налаштування'!$F$39:$K$100,6,FALSE),"ONBOARDING")="ACTIVE",INDEX('Розрахунок'!$H$5:$H$17,MATCH(F$4,'Розрахунок'!$A$5:$A$17,0)),"")} -> 0 | G9: {=IF(IFERROR(VLOOKUP(G$4,'Налаштування'!$F$39:$K$100,6,FALSE),"ONBOARDING")="ACTIVE",INDEX('Розрахунок'!$H$5:$H$17,MATCH(G$4,'Розрахунок'!$A$5:$A$17,0)),"")} -> 0 | H9: {=IF(IFERROR(VLOOKUP(H$4,'Налаштування'!$F$39:$K$100,6,FALSE),"ONBOARDING")="ACTIVE",INDEX('Розрахунок'!$H$5:$H$17,MATCH(H$4,'Розрахунок'!$A$5:$A$17,0)),"")} -> 0 | I9: {=IF(IFERROR(VLOOKUP(I$4,'Налаштування'!$F$39:$K$100,6,FALSE),"ONBOARDING")="ACTIVE",INDEX('Розрахунок'!$H$5:$H$17,MATCH(I$4,'Розрахунок'!$A$5:$A$17,0)),"")} -> 0 | ... N9: {=IF(IFERROR(VLOOKUP(N$4,'Налаштування'!$F$39:$K$100,6,FALSE),"ONBOARDING")="ACTIVE",INDEX('Розрахунок'!$H$5:$H$17,MATCH(N$4,'Розрахунок'!$A$5:$A$17,0)),"")} -> 0 | O9: {=IF(IFERROR(VLOOKUP(O$4,'Налаштування'!$F$39:$K$100,6,FALSE),"ONBOARDING")="ACTIVE",INDEX('Розрахунок'!$H$5:$H$18,MATCH(O$4,'Розрахунок'!$A$5:$A$18,0)),"")} -> 0 | P9: Частка домінантного дня серед attack-days за 56 днів
